Workbook
Name Counterparty_type: Values!$B$8:$B$32
Name Country: Values!$B$128:$B$388
Name Enum_Counterparty: [1]Values!$B$8:$B$32
Name Ind_CP_GCP: Values!$F$8:$F$12
Name Konsi_Errors: LER_02!$D$5
Name Konsi_Errors_01: LER_01!$D$9
Name Konsi_Warnings: LER_02!$D$6
Name NOGA: [1]Values!$B$36:$B$123
Name NOGA_Codes: Values!$B$36:$B$123

Sheet Delivery Note
G1: Survey | H1: LER
G2: Workbook | H2: LER
G3: Version | H3: 1.7
G4: FINMA code
G5: Reporting date | H5: 46203
G6: Reporting level | H6: K
B9: Large Exposure Reporting (LER)
B11: =IF(H6="K", "Group", "Parent") -> Group
D13: Please complete
B14: Company
B15: Department
B16: Address
B17: Post code/town
B18: Contact person
B19: Telephone
B20: E-mail
B22: Validation | D22: Errors | E22: Warnings
B23: LER_01 | D23: =[0]!Konsi_Errors_01 -> 0
B24: LER_02 | D24: =[0]!Konsi_Errors -> 0 | E24: =[0]!Konsi_Warnings -> 0
B26: Total | D26: =SUM(D23:D24) -> 0 | E26: =SUM(E24:E24) -> 0
B28: Submission deadline: LER: The forms, which are required on a semi-annually basis, must be submitted within six weeks.
B29: Explanations: Please read the explanations required for this survey at: | H29: Link EHP Erhebungs- und Eingabeformulare
B30: Technical questions on EHP: | H30: Link EHP Support
B31: Comments: Please use a separate document for your comments to this delivery and include
B32: ="the following details: your FINMA code ("&H4&"), survey ("&H1&") and reporting date ("&IF(ISTEXT(H5),H5,DAY(H5)&"."&MONTH(H5)&"."&YEAR(H5))&")." -> the following details: your FINMA code (), survey (LER) and reporting date (30.6.2026).
B35: Swiss Financial Market Supervisory Authority FINMA | H35: www.finma.ch
B36: Laupenstrasse 27
B37: CH-3003 Bern | F37: Technical questions on survey forms: | H37: ehp_banken@finma.ch
B38: Tel: +41 31 327 91 00 | F38: Subject-matter related questions on this survey: | H38: large.exposure@finma.ch

Sheet LER_01
O1: Form | P1: LER_01
O2: FINMA code | P2: ='Delivery Note'!H4 -> 0
O3: Reporting date | P3: ='Delivery Note'!H5 -> 46203
O4: Reporting level | P4: ='Delivery Note'!H6 -> K
B9: number of errors | D9: =COUNTIF(R26:X27,"ERROR") -> 0
B10: Bank category | C10: 10 | D10: 3 | K10: Amounts in 1'000 CHF
K20: Capital base | R20: LER_01_01 | T20: LER_01_02 | U20: LER_01_03 | V20: LER_01_04 | W20: LER_01_05 | X20: LER_01_06
K21: Tier 1 capital | L21: of which CET1 capital | M21: Hidden reserves | R21: Bank category | T21: Hidden reserves may only be reported if tier 1 capital is reported | U21: Hidden reserves > 0 for banks in categories 4 or 5 | V21: One and only one Tier 1 capital may be reported | W21: Tier 1 capital must be >= CET1 capital | X21: CET1 > 0 must be reported
K22: K | L22: L | M22: M
B26: either | D26: Current period | E26: 26 | K26: 1858372 | L26: 1507348 | R26: =IF(ISBLANK(D10),"ERROR","") | T26: =IF(ISBLANK(K26),IF(ISBLANK(M26),"","ERROR"),"") | U26: =IF(ISBLANK(M26),"",IF(AND(OR($D$10=4,$D$10=5),M26>0),"","ERROR")) | V26: =IF(K26+K27>0,IF(NOT(ISBLANK(K26)),IF(NOT(ISBLANK(K27)),"ERROR",""),""),"ERROR") | W26: =IF(ISBLANK(K26),"",IF(K26-L26<0,"ERROR","")) | X26: =IF(ISBLANK(K26),"",IF(L26<=0,"ERROR",""))
B27: or | D27: Previous period | E27: 27 | T27: =IF(ISBLANK(K27),IF(ISBLANK(M27),"","ERROR"),"") | U27: =IF(ISBLANK(M27),"",IF(AND(OR($D$10=4,$D$10=5),M27>0),"","ERROR")) | V27: =IF(K26+K27>0,IF(NOT(ISBLANK(K27)),IF(NOT(ISBLANK(K26)),"ERROR",""),""),"ERROR") | W27: =IF(ISBLANK(K27),"",IF(K27-L27<0,"ERROR","")) | X27: =IF(ISBLANK(K27),"",IF(L27<=0,"ERROR",""))

Sheet LER_02
P1: Form | Q1: LER_02
P2: FINMA code | Q2: ='Delivery Note'!H4 -> 0
P3: Reporting date | Q3: ='Delivery Note'!H5 -> 46203
P4: Reporting level | Q4: ='Delivery Note'!H6 -> K
B5: number of errors | D5: =COUNTIF(AS19:BE169,"ERROR") + COUNTIF(AS19:BE169,"=Duplicate") -> 0 | K5: Amounts in 1'000 CHF
B6: number of warnings | D6: =COUNTIF(AS19:BE169,"WARNING") -> 0
K16: Counterparty name | L16: Country of domicile ISO3-Code (e.g. CHE) | M16: Legal Entity Identifier (LEI) | N16: Enterprise Identification Number (UID) | O16: Counterparty ID following special characters excluded: < > & ' / | P16: Counterparty type | Q16: Affiliated party | R16: NOGA code Format '00' Range 01..99 | S16: Individual counterparty or group of connected counterparties | T16: Specific provisions / allowances | U16: Direct positions after credit conversion factors and net of specific provisions / allowances | AA16: Indirect positions from credit risk mitigation | AC16: Position before credit risk mitigation and before weighting, net of specific provisions / allowances | AD16: Credit risk mitigation impact (–) | AH16: Total position (after weighting) | AI16: Total adjusted position (after weighting) | AJ16: Total adjusted position (after weighting) as % of capital base (or CET1 in case of G0B/G0T) (automatically calculated) | AK16: Upper limit as % of capital base (automatically calculated) | AL16: Exceptional upper limit as % of capital base Note: Only to be filled in by banks subject to bank-specific temporary relief / tightening. | AM16: Pro memoria | AP16: Comment | AS16: LER_02_01 | AT16: LER_02_02 | AU16: LER_02_03 | AV16: LER_02_04 | AW16: LER_02_05 | AX16: LER_02_06 | AY16: LER_02_07 | AZ16: LER_02_08 | BA16: LER_02_09 | BB16: LER_02_10 | BC16: LER_02_11 | BD16: LER_02_12 | BE16: LER_02_13
U17: Off B/S positions | V17: Credit equivalent of derivatives | W17: Credit equivalent of SFTs | X17: Mortgages | Y17: Underlying and securities | Z17: Lending / Other positions | AA17: Financial collateral | AB17: Guarantees and credit derivatives | AD17: Netting | AE17: Credit derivatives | AF17: Financial collateral | AG17: Guarantees | AM17: Total adjusted position (after weighting) if CCF=100% applied to all off B/S positions | AN17: Total adjusted position (after weighting) excluding indirect positions from financial collateral within the 3-month grace period | AO17: End of 3-month grace period | AS17: Mandatory fields | AT17: LEI is a 20-character ID | AU17: UID: is a CHE plus 9 digits | AV17: Counterparty ID is unique | AW17: Total position before CRM is the sum of its parts | AX17: Total position after weighting and CRM is equal or less than position before CRM | AY17: Total position (AH) is greater than or equal to total adjusted position (AI) | AZ17: Total adjusted position (AI) is greater than or equal to total adjusted position after excluding indirect positions (AN) | BA17: Specific provisions/allowances have been reported as positive values | BB17: Column AD-AG are reported as negativ values only | BC17: End of grace period must be no more than 3 months in the future | BD17: G0T, G1T >= 0 must be present and positve | BE17: Exact counterpaty type must be specified for counterparty codes OTH and PDT
K18: K | L18: L | M18: M | N18: N | O18: O | P18: P | Q18: Q | R18: R | S18: S | T18: T | U18: U | V18: V | W18: W | X18: X | Y18: Y | Z18: Z | AA18: AA | AB18: AB | AC18: AC | AD18: AD | AE18: AE | AF18: AF | AG18: AG | AH18: AH | AI18: AI | AJ18: AJ | AK18: AK | AL18: AL | AM18: AM | AN18: AN | AO18: AO | AP18: AP
E19: 19 | K19: COUNTERPARTY 1 | L19: CHE | O19: GROUP 1 | P19: SOB | Q19: No | R19: 64 | S19: IND | V19: 5191.0411 | Y19: 770038.48 | Z19: 1003507.7 | AA19: 63.2214 | AC19: 1778800.4 | AH19: 1778800.4 | AI19: 1778800.4 | AJ19: =IF(P19="","",IFERROR(ROUND(IF(OR(P19="G0B",P19="G0T"),Tabelle5[[#This Row],[AI]]/SUM(LER_01!$L$26:$L$27),Tabelle5[[#This Row],[AI]]/(SUM(LER_01!$K$26:$K$27)+IF(LER_01!$D$10>=4,SUM(LER_01!$M$26:$M$27)))),3),"")) -> 0.957 | AK19: =IF(P19="","",IF(OR(P19="SOV",P19="SOB",P19="G0T",P19="G0B"),"",IF(AND(OR(P19="BSS",P19="BFS"),LER_01!$D$10<=2),15%,IF(AND(OR(P19="BSN",P19="BFN"),LER_01!$D$10>=4),100%,25%)))) | AM19: 1778800.4 | AS19: =IF(COUNTBLANK(K19:AP19)=32,"",IF(OR(COUNTA(K19,L19,O19,P19,Q19,R19,S19,AC19,AH19,AI19,AM19)=11,AND(OR(P19="G1T",P19="G0T"),COUNTA(AH19)=1)),"","ERROR")) | AT19: =IF(ISBLANK(M19),"",IF(LEN(M19)=20,"","ERROR")) | AU19: =IF(ISBLANK(N19),"",IF(AND(LEFT(N19,3)="CHE",ISNUMBER(MID(N19,4,9)+0),LEN(N19)=12),"","ERROR")) | AV19: =IF(COUNTIF(O$19:O$169,O19)>1,"Duplicate","") | AW19: =IF(ISBLANK(O19),"",IF(ABS(AC19-SUM(U19,V19,W19,X19,Y19,Z19,AA19,AB19))<=0.5,"","ERROR")) | AX19: =IF(ISBLANK(O19),"",IF(AC19+SUM(AD19,AE19,AF19,AG19)>=AH19-0.5,"","ERROR")) | AY19: =IF(ISBLANK(O19),"",IF(AH19>=AI19-0.5,"","ERROR")) | AZ19: =IF(ISBLANK(O19),"",IF(AI19>=AN19-0.5,"","ERROR")) | BA19: =IF(ISBLANK(O19),"",IF(T19>=0,"","ERROR")) | BB19: =IF(ISBLANK(O19),"",IF(COUNTIF(AD19:AG19,">0")>0,"ERROR","")) | BC19: =IF(ISBLANK(O19),"",IF(ISBLANK(AO19),"",IF(AO19>='Delivery Note'!$H$5,IF(AO19<='Delivery Note'!$H$5+92,"","ERROR"),"ERROR"))) | BD19: =IF(COUNTBLANK(K19:AP19)=32,"",IF(AND(COUNTIF(P$19:P$169,"G0T")>0,COUNTIF(P$19:P$169,"G1T")>0),IF(AND(OR(P19="G0T",P19="G1T"),OR(ISBLANK(AH19),AH19<0)),"WARNING",""),"WARNING")) | BE19: =IF(ISBLANK(P19),"",IF(AND(OR(P19="OTH", P19="PDT"), ISBLANK(AP19)), "WARNING", ""))
E20: 20 | K20: COUNTERPARTY 2 | L20: CHE | O20: GROUP 2 | P20: SOB | Q20: No | R20: 64 | S20: IND | Z20: 1768008.4 | AC20: 1768008.4 | AH20: 1768008.4 | AI20: 1768008.4 | AJ20: =IF(P20="","",IFERROR(ROUND(IF(OR(P20="G0B",P20="G0T"),Tabelle5[[#This Row],[AI]]/SUM(LER_01!$L$26:$L$27),Tabelle5[[#This Row],[AI]]/(SUM(LER_01!$K$26:$K$27)+IF(LER_01!$D$10>=4,SUM(LER_01!$M$26:$M$27)))),3),"")) -> 0.951 | AK20: =IF(P20="","",IF(OR(P20="SOV",P20="SOB",P20="G0T",P20="G0B"),"",IF(AND(OR(P20="BSS",P20="BFS"),LER_01!$D$10<=2),15%,IF(AND(OR(P20="BSN",P20="BFN"),LER_01!$D$10>=4),100%,25%)))) | AM20: 1768008.4 | AS20: =IF(COUNTBLANK(K20:AP20)=32,"",IF(OR(COUNTA(K20,L20,O20,P20,Q20,R20,S20,AC20,AH20,AI20,AM20)=11,AND(OR(P20="G1T",P20="G0T"),COUNTA(AH20)=1)),"","ERROR")) | AT20: =IF(ISBLANK(M20),"",IF(LEN(M20)=20,"","ERROR")) | AU20: =IF(ISBLANK(N20),"",IF(AND(LEFT(N20,3)="CHE",ISNUMBER(MID(N20,4,9)+0),LEN(N20)=12),"","ERROR")) | AV20: =IF(COUNTIF(O$19:O$169,O20)>1,"Duplicate","") | AW20: =IF(ISBLANK(O20),"",IF(ABS(AC20-SUM(U20,V20,W20,X20,Y20,Z20,AA20,AB20))<=0.5,"","ERROR")) | AX20: =IF(ISBLANK(O20),"",IF(AC20+SUM(AD20,AE20,AF20,AG20)>=AH20-0.5,"","ERROR")) | AY20: =IF(ISBLANK(O20),"",IF(AH20>=AI20-0.5,"","ERROR")) | AZ20: =IF(ISBLANK(O20),"",IF(AI20>=AN20-0.5,"","ERROR")) | BA20: =IF(ISBLANK(O20),"",IF(T20>=0,"","ERROR")) | BB20: =IF(ISBLANK(O20),"",IF(COUNTIF(AD20:AG20,">0")>0,"ERROR","")) | BC20: =IF(ISBLANK(O20),"",IF(ISBLANK(AO20),"",IF(AO20>='Delivery Note'!$H$5,IF(AO20<='Delivery Note'!$H$5+92,"","ERROR"),"ERROR"))) | BD20: =IF(COUNTBLANK(K20:AP20)=32,"",IF(AND(COUNTIF(P$19:P$169,"G0T")>0,COUNTIF(P$19:P$169,"G1T")>0),IF(AND(OR(P20="G0T",P20="G1T"),OR(ISBLANK(AH20),AH20<0)),"WARNING",""),"WARNING")) | BE20: =IF(ISBLANK(P20),"",IF(AND(OR(P20="OTH", P20="PDT"), ISBLANK(AP20)), "WARNING", ""))
E21: 21 | K21: COUNTERPARTY 3 | L21: CHE | O21: GROUP 3 | P21: SOV | Q21: No | R21: 84 | S21: IND | Y21: 1584102 | AA21: 168290.41 | AC21: 1752392.4 | AH21: 1752392.4 | AI21: 1752392.4 | AJ21: =IF(P21="","",IFERROR(ROUND(IF(OR(P21="G0B",P21="G0T"),Tabelle5[[#This Row],[AI]]/SUM(LER_01!$L$26:$L$27),Tabelle5[[#This Row],[AI]]/(SUM(LER_01!$K$26:$K$27)+IF(LER_01!$D$10>=4,SUM(LER_01!$M$26:$M$27)))),3),"")) -> 0.943 | AK21: =IF(P21="","",IF(OR(P21="SOV",P21="SOB",P21="G0T",P21="G0B"),"",IF(AND(OR(P21="BSS",P21="BFS"),LER_01!$D$10<=2),15%,IF(AND(OR(P21="BSN",P21="BFN"),LER_01!$D$10>=4),100%,25%)))) | AM21: 1752392.4 | AS21: =IF(COUNTBLANK(K21:AP21)=32,"",IF(OR(COUNTA(K21,L21,O21,P21,Q21,R21,S21,AC21,AH21,AI21,AM21)=11,AND(OR(P21="G1T",P21="G0T"),COUNTA(AH21)=1)),"","ERROR")) | AT21: =IF(ISBLANK(M21),"",IF(LEN(M21)=20,"","ERROR")) | AU21: =IF(ISBLANK(N21),"",IF(AND(LEFT(N21,3)="CHE",ISNUMBER(MID(N21,4,9)+0),LEN(N21)=12),"","ERROR")) | AV21: =IF(COUNTIF(O$19:O$169,O21)>1,"Duplicate","") | AW21: =IF(ISBLANK(O21),"",IF(ABS(AC21-SUM(U21,V21,W21,X21,Y21,Z21,AA21,AB21))<=0.5,"","ERROR")) | AX21: =IF(ISBLANK(O21),"",IF(AC21+SUM(AD21,AE21,AF21,AG21)>=AH21-0.5,"","ERROR")) | AY21: =IF(ISBLANK(O21),"",IF(AH21>=AI21-0.5,"","ERROR")) | AZ21: =IF(ISBLANK(O21),"",IF(AI21>=AN21-0.5,"","ERROR")) | BA21: =IF(ISBLANK(O21),"",IF(T21>=0,"","ERROR")) | BB21: =IF(ISBLANK(O21),"",IF(COUNTIF(AD21:AG21,">0")>0,"ERROR","")) | BC21: =IF(ISBLANK(O21),"",IF(ISBLANK(AO21),"",IF(AO21>='Delivery Note'!$H$5,IF(AO21<='Delivery Note'!$H$5+92,"","ERROR"),"ERROR"))) | BD21: =IF(COUNTBLANK(K21:AP21)=32,"",IF(AND(COUNTIF(P$19:P$169,"G0T")>0,COUNTIF(P$19:P$169,"G1T")>0),IF(AND(OR(P21="G0T",P21="G1T"),OR(ISBLANK(AH21),AH21<0)),"WARNING",""),"WARNING")) | BE21: =IF(ISBLANK(P21),"",IF(AND(OR(P21="OTH", P21="PDT"), ISBLANK(AP21)), "WARNING", ""))
E22: 22 | K22: COUNTERPARTY 4 | L22: CHE | O22: GROUP 4 | P22: SOO | Q22: No | R22: 99 | S22: IND | Y22: 1574067 | AA22: 1426.139 | AC22: 1575493.1 | AH22: 1575493.1 | AI22: 1575493.1 | AJ22: =IF(P22="","",IFERROR(ROUND(IF(OR(P22="G0B",P22="G0T"),Tabelle5[[#This Row],[AI]]/SUM(LER_01!$L$26:$L$27),Tabelle5[[#This Row],[AI]]/(SUM(LER_01!$K$26:$K$27)+IF(LER_01!$D$10>=4,SUM(LER_01!$M$26:$M$27)))),3),"")) -> 0.848 | AK22: =IF(P22="","",IF(OR(P22="SOV",P22="SOB",P22="G0T",P22="G0B"),"",IF(AND(OR(P22="BSS",P22="BFS"),LER_01!$D$10<=2),15%,IF(AND(OR(P22="BSN",P22="BFN"),LER_01!$D$10>=4),100%,25%)))) -> 0.25 | AM22: 1575493.1 | AS22: =IF(COUNTBLANK(K22:AP22)=32,"",IF(OR(COUNTA(K22,L22,O22,P22,Q22,R22,S22,AC22,AH22,AI22,AM22)=11,AND(OR(P22="G1T",P22="G0T"),COUNTA(AH22)=1)),"","ERROR")) | AT22: =IF(ISBLANK(M22),"",IF(LEN(M22)=20,"","ERROR")) | AU22: =IF(ISBLANK(N22),"",IF(AND(LEFT(N22,3)="CHE",ISNUMBER(MID(N22,4,9)+0),LEN(N22)=12),"","ERROR")) | AV22: =IF(COUNTIF(O$19:O$169,O22)>1,"Duplicate","") | AW22: =IF(ISBLANK(O22),"",IF(ABS(AC22-SUM(U22,V22,W22,X22,Y22,Z22,AA22,AB22))<=0.5,"","ERROR")) | AX22: =IF(ISBLANK(O22),"",IF(AC22+SUM(AD22,AE22,AF22,AG22)>=AH22-0.5,"","ERROR")) | AY22: =IF(ISBLANK(O22),"",IF(AH22>=AI22-0.5,"","ERROR")) | AZ22: =IF(ISBLANK(O22),"",IF(AI22>=AN22-0.5,"","ERROR")) | BA22: =IF(ISBLANK(O22),"",IF(T22>=0,"","ERROR")) | BB22: =IF(ISBLANK(O22),"",IF(COUNTIF(AD22:AG22,">0")>0,"ERROR","")) | BC22: =IF(ISBLANK(O22),"",IF(ISBLANK(AO22),"",IF(AO22>='Delivery Note'!$H$5,IF(AO22<='Delivery Note'!$H$5+92,"","ERROR"),"ERROR"))) | BD22: =IF(COUNTBLANK(K22:AP22)=32,"",IF(AND(COUNTIF(P$19:P$169,"G0T")>0,COUNTIF(P$19:P$169,"G1T")>0),IF(AND(OR(P22="G0T",P22="G1T"),OR(ISBLANK(AH22),AH22<0)),"WARNING",""),"WARNING")) | BE22: =IF(ISBLANK(P22),"",IF(AND(OR(P22="OTH", P22="PDT"), ISBLANK(AP22)), "WARNING", ""))
E23: 23 | K23: COUNTERPARTY 5 | L23: CHE | O23: GROUP 5 | P23: SOB | Q23: No | R23: 64 | S23: IND | Y23: 979904.19 | Z23: 12251.408 | AC23: 992155.6 | AH23: 992155.6 | AI23: 992155.6 | AJ23: =IF(P23="","",IFERROR(ROUND(IF(OR(P23="G0B",P23="G0T"),Tabelle5[[#This Row],[AI]]/SUM(LER_01!$L$26:$L$27),Tabelle5[[#This Row],[AI]]/(SUM(LER_01!$K$26:$K$27)+IF(LER_01!$D$10>=4,SUM(LER_01!$M$26:$M$27)))),3),"")) -> 0.534 | AK23: =IF(P23="","",IF(OR(P23="SOV",P23="SOB",P23="G0T",P23="G0B"),"",IF(AND(OR(P23="BSS",P23="BFS"),LER_01!$D$10<=2),15%,IF(AND(OR(P23="BSN",P23="BFN"),LER_01!$D$10>=4),100%,25%)))) | AM23: 992155.6 | AS23: =IF(COUNTBLANK(K23:AP23)=32,"",IF(OR(COUNTA(K23,L23,O23,P23,Q23,R23,S23,AC23,AH23,AI23,AM23)=11,AND(OR(P23="G1T",P23="G0T"),COUNTA(AH23)=1)),"","ERROR")) | AT23: =IF(ISBLANK(M23),"",IF(LEN(M23)=20,"","ERROR")) | AU23: =IF(ISBLANK(N23),"",IF(AND(LEFT(N23,3)="CHE",ISNUMBER(MID(N23,4,9)+0),LEN(N23)=12),"","ERROR")) | AV23: =IF(COUNTIF(O$19:O$169,O23)>1,"Duplicate","") | AW23: =IF(ISBLANK(O23),"",IF(ABS(AC23-SUM(U23,V23,W23,X23,Y23,Z23,AA23,AB23))<=0.5,"","ERROR")) | AX23: =IF(ISBLANK(O23),"",IF(AC23+SUM(AD23,AE23,AF23,AG23)>=AH23-0.5,"","ERROR")) | AY23: =IF(ISBLANK(O23),"",IF(AH23>=AI23-0.5,"","ERROR")) | AZ23: =IF(ISBLANK(O23),"",IF(AI23>=AN23-0.5,"","ERROR")) | BA23: =IF(ISBLANK(O23),"",IF(T23>=0,"","ERROR")) | BB23: =IF(ISBLANK(O23),"",IF(COUNTIF(AD23:AG23,">0")>0,"ERROR","")) | BC23: =IF(ISBLANK(O23),"",IF(ISBLANK(AO23),"",IF(AO23>='Delivery Note'!$H$5,IF(AO23<='Delivery Note'!$H$5+92,"","ERROR"),"ERROR"))) | BD23: =IF(COUNTBLANK(K23:AP23)=32,"",IF(AND(COUNTIF(P$19:P$169,"G0T")>0,COUNTIF(P$19:P$169,"G1T")>0),IF(AND(OR(P23="G0T",P23="G1T"),OR(ISBLANK(AH23),AH23<0)),"WARNING",""),"WARNING")) | BE23: =IF(ISBLANK(P23),"",IF(AND(OR(P23="OTH", P23="PDT"), ISBLANK(AP23)), "WARNING", ""))
E24: 24 | K24: COUNTERPARTY 6 | L24: CHE | O24: GROUP 6 | P24: SOV | Q24: No | R24: 84 | S24: IND | AA24: 12929.493 | AB24: 852401.49 | AC24: 865330.98 | AH24: 865330.98 | AI24: 865330.98 | AJ24: =IF(P24="","",IFERROR(ROUND(IF(OR(P24="G0B",P24="G0T"),Tabelle5[[#This Row],[AI]]/SUM(LER_01!$L$26:$L$27),Tabelle5[[#This Row],[AI]]/(SUM(LER_01!$K$26:$K$27)+IF(LER_01!$D$10>=4,SUM(LER_01!$M$26:$M$27)))),3),"")) -> 0.466 | AK24: =IF(P24="","",IF(OR(P24="SOV",P24="SOB",P24="G0T",P24="G0B"),"",IF(AND(OR(P24="BSS",P24="BFS"),LER_01!$D$10<=2),15%,IF(AND(OR(P24="BSN",P24="BFN"),LER_01!$D$10>=4),100%,25%)))) | AM24: 865330.98 | AS24: =IF(COUNTBLANK(K24:AP24)=32,"",IF(OR(COUNTA(K24,L24,O24,P24,Q24,R24,S24,AC24,AH24,AI24,AM24)=11,AND(OR(P24="G1T",P24="G0T"),COUNTA(AH24)=1)),"","ERROR")) | AT24: =IF(ISBLANK(M24),"",IF(LEN(M24)=20,"","ERROR")) | AU24: =IF(ISBLANK(N24),"",IF(AND(LEFT(N24,3)="CHE",ISNUMBER(MID(N24,4,9)+0),LEN(N24)=12),"","ERROR")) | AV24: =IF(COUNTIF(O$19:O$169,O24)>1,"Duplicate","") | AW24: =IF(ISBLANK(O24),"",IF(ABS(AC24-SUM(U24,V24,W24,X24,Y24,Z24,AA24,AB24))<=0.5,"","ERROR")) | AX24: =IF(ISBLANK(O24),"",IF(AC24+SUM(AD24,AE24,AF24,AG24)>=AH24-0.5,"","ERROR")) | AY24: =IF(ISBLANK(O24),"",IF(AH24>=AI24-0.5,"","ERROR")) | AZ24: =IF(ISBLANK(O24),"",IF(AI24>=AN24-0.5,"","ERROR")) | BA24: =IF(ISBLANK(O24),"",IF(T24>=0,"","ERROR")) | BB24: =IF(ISBLANK(O24),"",IF(COUNTIF(AD24:AG24,">0")>0,"ERROR","")) | BC24: =IF(ISBLANK(O24),"",IF(ISBLANK(AO24),"",IF(AO24>='Delivery Note'!$H$5,IF(AO24<='Delivery Note'!$H$5+92,"","ERROR"),"ERROR"))) | BD24: =IF(COUNTBLANK(K24:AP24)=32,"",IF(AND(COUNTIF(P$19:P$169,"G0T")>0,COUNTIF(P$19:P$169,"G1T")>0),IF(AND(OR(P24="G0T",P24="G1T"),OR(ISBLANK(AH24),AH24<0)),"WARNING",""),"WARNING")) | BE24: =IF(ISBLANK(P24),"",IF(AND(OR(P24="OTH", P24="PDT"), ISBLANK(AP24)), "WARNING", ""))
E25: 25 | K25: COUNTERPARTY 7 | L25: CHE | O25: GROUP 7 | P25: SOB | Q25: No | R25: 64 | S25: IND | Z25: 861929.99 | AC25: 861929.99 | AH25: 861929.99 | AI25: 861929.99 | AJ25: =IF(P25="","",IFERROR(ROUND(IF(OR(P25="G0B",P25="G0T"),Tabelle5[[#This Row],[AI]]/SUM(LER_01!$L$26:$L$27),Tabelle5[[#This Row],[AI]]/(SUM(LER_01!$K$26:$K$27)+IF(LER_01!$D$10>=4,SUM(LER_01!$M$26:$M$27)))),3),"")) -> 0.464 | AK25: =IF(P25="","",IF(OR(P25="SOV",P25="SOB",P25="G0T",P25="G0B"),"",IF(AND(OR(P25="BSS",P25="BFS"),LER_01!$D$10<=2),15%,IF(AND(OR(P25="BSN",P25="BFN"),LER_01!$D$10>=4),100%,25%)))) | AM25: 861929.99 | AS25: =IF(COUNTBLANK(K25:AP25)=32,"",IF(OR(COUNTA(K25,L25,O25,P25,Q25,R25,S25,AC25,AH25,AI25,AM25)=11,AND(OR(P25="G1T",P25="G0T"),COUNTA(AH25)=1)),"","ERROR")) | AT25: =IF(ISBLANK(M25),"",IF(LEN(M25)=20,"","ERROR")) | AU25: =IF(ISBLANK(N25),"",IF(AND(LEFT(N25,3)="CHE",ISNUMBER(MID(N25,4,9)+0),LEN(N25)=12),"","ERROR")) | AV25: =IF(COUNTIF(O$19:O$169,O25)>1,"Duplicate","") | AW25: =IF(ISBLANK(O25),"",IF(ABS(AC25-SUM(U25,V25,W25,X25,Y25,Z25,AA25,AB25))<=0.5,"","ERROR")) | AX25: =IF(ISBLANK(O25),"",IF(AC25+SUM(AD25,AE25,AF25,AG25)>=AH25-0.5,"","ERROR")) | AY25: =IF(ISBLANK(O25),"",IF(AH25>=AI25-0.5,"","ERROR")) | AZ25: =IF(ISBLANK(O25),"",IF(AI25>=AN25-0.5,"","ERROR")) | BA25: =IF(ISBLANK(O25),"",IF(T25>=0,"","ERROR")) | BB25: =IF(ISBLANK(O25),"",IF(COUNTIF(AD25:AG25,">0")>0,"ERROR","")) | BC25: =IF(ISBLANK(O25),"",IF(ISBLANK(AO25),"",IF(AO25>='Delivery Note'!$H$5,IF(AO25<='Delivery Note'!$H$5+92,"","ERROR"),"ERROR"))) | BD25: =IF(COUNTBLANK(K25:AP25)=32,"",IF(AND(COUNTIF(P$19:P$169,"G0T")>0,COUNTIF(P$19:P$169,"G1T")>0),IF(AND(OR(P25="G0T",P25="G1T"),OR(ISBLANK(AH25),AH25<0)),"WARNING",""),"WARNING")) | BE25: =IF(ISBLANK(P25),"",IF(AND(OR(P25="OTH", P25="PDT"), ISBLANK(AP25)), "WARNING", ""))
E26: 26 | K26: COUNTERPARTY 8 | L26: CHE | O26: GROUP 8 | P26: BFN | Q26: No | R26: 64 | S26: IND | Y26: 632084.7 | AA26: 368.13867 | AC26: 632452.84 | AG26: -632084.7 | AH26: 368.13867 | AI26: 368.13867 | AJ26: =IF(P26="","",IFERROR(ROUND(IF(OR(P26="G0B",P26="G0T"),Tabelle5[[#This Row],[AI]]/SUM(LER_01!$L$26:$L$27),Tabelle5[[#This Row],[AI]]/(SUM(LER_01!$K$26:$K$27)+IF(LER_01!$D$10>=4,SUM(LER_01!$M$26:$M$27)))),3),"")) -> 0 | AK26: =IF(P26="","",IF(OR(P26="SOV",P26="SOB",P26="G0T",P26="G0B"),"",IF(AND(OR(P26="BSS",P26="BFS"),LER_01!$D$10<=2),15%,IF(AND(OR(P26="BSN",P26="BFN"),LER_01!$D$10>=4),100%,25%)))) -> 0.25 | AM26: 368.13867 | AS26: =IF(COUNTBLANK(K26:AP26)=32,"",IF(OR(COUNTA(K26,L26,O26,P26,Q26,R26,S26,AC26,AH26,AI26,AM26)=11,AND(OR(P26="G1T",P26="G0T"),COUNTA(AH26)=1)),"","ERROR")) | AT26: =IF(ISBLANK(M26),"",IF(LEN(M26)=20,"","ERROR")) | AU26: =IF(ISBLANK(N26),"",IF(AND(LEFT(N26,3)="CHE",ISNUMBER(MID(N26,4,9)+0),LEN(N26)=12),"","ERROR")) | AV26: =IF(COUNTIF(O$19:O$169,O26)>1,"Duplicate","") | AW26: =IF(ISBLANK(O26),"",IF(ABS(AC26-SUM(U26,V26,W26,X26,Y26,Z26,AA26,AB26))<=0.5,"","ERROR")) | AX26: =IF(ISBLANK(O26),"",IF(AC26+SUM(AD26,AE26,AF26,AG26)>=AH26-0.5,"","ERROR")) | AY26: =IF(ISBLANK(O26),"",IF(AH26>=AI26-0.5,"","ERROR")) | AZ26: =IF(ISBLANK(O26),"",IF(AI26>=AN26-0.5,"","ERROR")) | BA26: =IF(ISBLANK(O26),"",IF(T26>=0,"","ERROR")) | BB26: =IF(ISBLANK(O26),"",IF(COUNTIF(AD26:AG26,">0")>0,"ERROR","")) | BC26: =IF(ISBLANK(O26),"",IF(ISBLANK(AO26),"",IF(AO26>='Delivery Note'!$H$5,IF(AO26<='Delivery Note'!$H$5+92,"","ERROR"),"ERROR"))) | BD26: =IF(COUNTBLANK(K26:AP26)=32,"",IF(AND(COUNTIF(P$19:P$169,"G0T")>0,COUNTIF(P$19:P$169,"G1T")>0),IF(AND(OR(P26="G0T",P26="G1T"),OR(ISBLANK(AH26),AH26<0)),"WARNING",""),"WARNING")) | BE26: =IF(ISBLANK(P26),"",IF(AND(OR(P26="OTH", P26="PDT"), ISBLANK(AP26)), "WARNING", ""))
E27: 27 | K27: COUNTERPARTY 9 | L27: CHE | O27: GROUP 9 | P27: SOV | Q27: No | R27: 84 | S27: IND | Y27: 92659.749 | AA27: 7695.5699 | AB27: 525300.63 | AC27: 625655.95 | AH27: 625655.95 | AI27: 625655.95 | AJ27: =IF(P27="","",IFERROR(ROUND(IF(OR(P27="G0B",P27="G0T"),Tabelle5[[#This Row],[AI]]/SUM(LER_01!$L$26:$L$27),Tabelle5[[#This Row],[AI]]/(SUM(LER_01!$K$26:$K$27)+IF(LER_01!$D$10>=4,SUM(LER_01!$M$26:$M$27)))),3),"")) -> 0.337 | AK27: =IF(P27="","",IF(OR(P27="SOV",P27="SOB",P27="G0T",P27="G0B"),"",IF(AND(OR(P27="BSS",P27="BFS"),LER_01!$D$10<=2),15%,IF(AND(OR(P27="BSN",P27="BFN"),LER_01!$D$10>=4),100%,25%)))) | AM27: 625655.95 | AS27: =IF(COUNTBLANK(K27:AP27)=32,"",IF(OR(COUNTA(K27,L27,O27,P27,Q27,R27,S27,AC27,AH27,AI27,AM27)=11,AND(OR(P27="G1T",P27="G0T"),COUNTA(AH27)=1)),"","ERROR")) | AT27: =IF(ISBLANK(M27),"",IF(LEN(M27)=20,"","ERROR")) | AU27: =IF(ISBLANK(N27),"",IF(AND(LEFT(N27,3)="CHE",ISNUMBER(MID(N27,4,9)+0),LEN(N27)=12),"","ERROR")) | AV27: =IF(COUNTIF(O$19:O$169,O27)>1,"Duplicate","") | AW27: =IF(ISBLANK(O27),"",IF(ABS(AC27-SUM(U27,V27,W27,X27,Y27,Z27,AA27,AB27))<=0.5,"","ERROR")) | AX27: =IF(ISBLANK(O27),"",IF(AC27+SUM(AD27,AE27,AF27,AG27)>=AH27-0.5,"","ERROR")) | AY27: =IF(ISBLANK(O27),"",IF(AH27>=AI27-0.5,"","ERROR")) | AZ27: =IF(ISBLANK(O27),"",IF(AI27>=AN27-0.5,"","ERROR")) | BA27: =IF(ISBLANK(O27),"",IF(T27>=0,"","ERROR")) | BB27: =IF(ISBLANK(O27),"",IF(COUNTIF(AD27:AG27,">0")>0,"ERROR","")) | BC27: =IF(ISBLANK(O27),"",IF(ISBLANK(AO27),"",IF(AO27>='Delivery Note'!$H$5,IF(AO27<='Delivery Note'!$H$5+92,"","ERROR"),"ERROR"))) | BD27: =IF(COUNTBLANK(K27:AP27)=32,"",IF(AND(COUNTIF(P$19:P$169,"G0T")>0,COUNTIF(P$19:P$169,"G1T")>0),IF(AND(OR(P27="G0T",P27="G1T"),OR(ISBLANK(AH27),AH27<0)),"WARNING",""),"WARNING")) | BE27: =IF(ISBLANK(P27),"",IF(AND(OR(P27="OTH", P27="PDT"), ISBLANK(AP27)), "WARNING", ""))
E28: 28 | K28: COUNTERPARTY 10 | L28: CHE | O28: GROUP 10 | P28: SOV | Q28: No | R28: 84 | S28: IND | Y28: 48310.016 | AA28: 502.02607 | AB28: 435850.26 | AC28: 484662.3 | AH28: 484662.3 | AI28: 484662.3 | AJ28: =IF(P28="","",IFERROR(ROUND(IF(OR(P28="G0B",P28="G0T"),Tabelle5[[#This Row],[AI]]/SUM(LER_01!$L$26:$L$27),Tabelle5[[#This Row],[AI]]/(SUM(LER_01!$K$26:$K$27)+IF(LER_01!$D$10>=4,SUM(LER_01!$M$26:$M$27)))),3),"")) -> 0.261 | AK28: =IF(P28="","",IF(OR(P28="SOV",P28="SOB",P28="G0T",P28="G0B"),"",IF(AND(OR(P28="BSS",P28="BFS"),LER_01!$D$10<=2),15%,IF(AND(OR(P28="BSN",P28="BFN"),LER_01!$D$10>=4),100%,25%)))) | AM28: 484662.3 | AS28: =IF(COUNTBLANK(K28:AP28)=32,"",IF(OR(COUNTA(K28,L28,O28,P28,Q28,R28,S28,AC28,AH28,AI28,AM28)=11,AND(OR(P28="G1T",P28="G0T"),COUNTA(AH28)=1)),"","ERROR")) | AT28: =IF(ISBLANK(M28),"",IF(LEN(M28)=20,"","ERROR")) | AU28: =IF(ISBLANK(N28),"",IF(AND(LEFT(N28,3)="CHE",ISNUMBER(MID(N28,4,9)+0),LEN(N28)=12),"","ERROR")) | AV28: =IF(COUNTIF(O$19:O$169,O28)>1,"Duplicate","") | AW28: =IF(ISBLANK(O28),"",IF(ABS(AC28-SUM(U28,V28,W28,X28,Y28,Z28,AA28,AB28))<=0.5,"","ERROR")) | AX28: =IF(ISBLANK(O28),"",IF(AC28+SUM(AD28,AE28,AF28,AG28)>=AH28-0.5,"","ERROR")) | AY28: =IF(ISBLANK(O28),"",IF(AH28>=AI28-0.5,"","ERROR")) | AZ28: =IF(ISBLANK(O28),"",IF(AI28>=AN28-0.5,"","ERROR")) | BA28: =IF(ISBLANK(O28),"",IF(T28>=0,"","ERROR")) | BB28: =IF(ISBLANK(O28),"",IF(COUNTIF(AD28:AG28,">0")>0,"ERROR","")) | BC28: =IF(ISBLANK(O28),"",IF(ISBLANK(AO28),"",IF(AO28>='Delivery Note'!$H$5,IF(AO28<='Delivery Note'!$H$5+92,"","ERROR"),"ERROR"))) | BD28: =IF(COUNTBLANK(K28:AP28)=32,"",IF(AND(COUNTIF(P$19:P$169,"G0T")>0,COUNTIF(P$19:P$169,"G1T")>0),IF(AND(OR(P28="G0T",P28="G1T"),OR(ISBLANK(AH28),AH28<0)),"WARNING",""),"WARNING")) | BE28: =IF(ISBLANK(P28),"",IF(AND(OR(P28="OTH", P28="PDT"), ISBLANK(AP28)), "WARNING", ""))
E29: 29 | K29: COUNTERPARTY 11 | L29: CHE | O29: GROUP 11 | P29: SOB | Q29: No | R29: 64 | S29: IND | Y29: 12057.866 | Z29: 406679.82 | AC29: 418737.69 | AH29: 418737.69 | AI29: 418737.69 | AJ29: =IF(P29="","",IFERROR(ROUND(IF(OR(P29="G0B",P29="G0T"),Tabelle5[[#This Row],[AI]]/SUM(LER_01!$L$26:$L$27),Tabelle5[[#This Row],[AI]]/(SUM(LER_01!$K$26:$K$27)+IF(LER_01!$D$10>=4,SUM(LER_01!$M$26:$M$27)))),3),"")) -> 0.225 | AK29: =IF(P29="","",IF(OR(P29="SOV",P29="SOB",P29="G0T",P29="G0B"),"",IF(AND(OR(P29="BSS",P29="BFS"),LER_01!$D$10<=2),15%,IF(AND(OR(P29="BSN",P29="BFN"),LER_01!$D$10>=4),100%,25%)))) | AM29: 418737.69 | AS29: =IF(COUNTBLANK(K29:AP29)=32,"",IF(OR(COUNTA(K29,L29,O29,P29,Q29,R29,S29,AC29,AH29,AI29,AM29)=11,AND(OR(P29="G1T",P29="G0T"),COUNTA(AH29)=1)),"","ERROR")) | AT29: =IF(ISBLANK(M29),"",IF(LEN(M29)=20,"","ERROR")) | AU29: =IF(ISBLANK(N29),"",IF(AND(LEFT(N29,3)="CHE",ISNUMBER(MID(N29,4,9)+0),LEN(N29)=12),"","ERROR")) | AV29: =IF(COUNTIF(O$19:O$169,O29)>1,"Duplicate","") | AW29: =IF(ISBLANK(O29),"",IF(ABS(AC29-SUM(U29,V29,W29,X29,Y29,Z29,AA29,AB29))<=0.5,"","ERROR")) | AX29: =IF(ISBLANK(O29),"",IF(AC29+SUM(AD29,AE29,AF29,AG29)>=AH29-0.5,"","ERROR")) | AY29: =IF(ISBLANK(O29),"",IF(AH29>=AI29-0.5,"","ERROR")) | AZ29: =IF(ISBLANK(O29),"",IF(AI29>=AN29-0.5,"","ERROR")) | BA29: =IF(ISBLANK(O29),"",IF(T29>=0,"","ERROR")) | BB29: =IF(ISBLANK(O29),"",IF(COUNTIF(AD29:AG29,">0")>0,"ERROR","")) | BC29: =IF(ISBLANK(O29),"",IF(ISBLANK(AO29),"",IF(AO29>='Delivery Note'!$H$5,IF(AO29<='Delivery Note'!$H$5+92,"","ERROR"),"ERROR"))) | BD29: =IF(COUNTBLANK(K29:AP29)=32,"",IF(AND(COUNTIF(P$19:P$169,"G0T")>0,COUNTIF(P$19:P$169,"G1T")>0),IF(AND(OR(P29="G0T",P29="G1T"),OR(ISBLANK(AH29),AH29<0)),"WARNING",""),"WARNING")) | BE29: =IF(ISBLANK(P29),"",IF(AND(OR(P29="OTH", P29="PDT"), ISBLANK(AP29)), "WARNING", ""))
E30: 30 | K30: COUNTERPARTY 12 | L30: CHE | O30: GROUP 12 | P30: BFN | Q30: No | R30: 64 | S30: IND | W30: 0.00155 | Z30: 323819.6 | AC30: 323819.6 | AF30: -323819.6 | AH30: 0 | AI30: 0 | AJ30: =IF(P30="","",IFERROR(ROUND(IF(OR(P30="G0B",P30="G0T"),Tabelle5[[#This Row],[AI]]/SUM(LER_01!$L$26:$L$27),Tabelle5[[#This Row],[AI]]/(SUM(LER_01!$K$26:$K$27)+IF(LER_01!$D$10>=4,SUM(LER_01!$M$26:$M$27)))),3),"")) -> 0 | AK30: =IF(P30="","",IF(OR(P30="SOV",P30="SOB",P30="G0T",P30="G0B"),"",IF(AND(OR(P30="BSS",P30="BFS"),LER_01!$D$10<=2),15%,IF(AND(OR(P30="BSN",P30="BFN"),LER_01!$D$10>=4),100%,25%)))) -> 0.25 | AM30: 0 | AS30: =IF(COUNTBLANK(K30:AP30)=32,"",IF(OR(COUNTA(K30,L30,O30,P30,Q30,R30,S30,AC30,AH30,AI30,AM30)=11,AND(OR(P30="G1T",P30="G0T"),COUNTA(AH30)=1)),"","ERROR")) | AT30: =IF(ISBLANK(M30),"",IF(LEN(M30)=20,"","ERROR")) | AU30: =IF(ISBLANK(N30),"",IF(AND(LEFT(N30,3)="CHE",ISNUMBER(MID(N30,4,9)+0),LEN(N30)=12),"","ERROR")) | AV30: =IF(COUNTIF(O$19:O$169,O30)>1,"Duplicate","") | AW30: =IF(ISBLANK(O30),"",IF(ABS(AC30-SUM(U30,V30,W30,X30,Y30,Z30,AA30,AB30))<=0.5,"","ERROR")) | AX30: =IF(ISBLANK(O30),"",IF(AC30+SUM(AD30,AE30,AF30,AG30)>=AH30-0.5,"","ERROR")) | AY30: =IF(ISBLANK(O30),"",IF(AH30>=AI30-0.5,"","ERROR")) | AZ30: =IF(ISBLANK(O30),"",IF(AI30>=AN30-0.5,"","ERROR")) | BA30: =IF(ISBLANK(O30),"",IF(T30>=0,"","ERROR")) | BB30: =IF(ISBLANK(O30),"",IF(COUNTIF(AD30:AG30,">0")>0,"ERROR","")) | BC30: =IF(ISBLANK(O30),"",IF(ISBLANK(AO30),"",IF(AO30>='Delivery Note'!$H$5,IF(AO30<='Delivery Note'!$H$5+92,"","ERROR"),"ERROR"))) | BD30: =IF(COUNTBLANK(K30:AP30)=32,"",IF(AND(COUNTIF(P$19:P$169,"G0T")>0,COUNTIF(P$19:P$169,"G1T")>0),IF(AND(OR(P30="G0T",P30="G1T"),OR(ISBLANK(AH30),AH30<0)),"WARNING",""),"WARNING")) | BE30: =IF(ISBLANK(P30),"",IF(AND(OR(P30="OTH", P30="PDT"), ISBLANK(AP30)), "WARNING", ""))
E31: 31 | K31: COUNTERPARTY 13 | L31: CHE | O31: GROUP 13 | P31: SOV | Q31: No | R31: 84 | S31: IND | AA31: 712.98758 | AB31: 319879.68 | AC31: 320592.67 | AH31: 320592.67 | AI31: 320592.67 | AJ31: =IF(P31="","",IFERROR(ROUND(IF(OR(P31="G0B",P31="G0T"),Tabelle5[[#This Row],[AI]]/SUM(LER_01!$L$26:$L$27),Tabelle5[[#This Row],[AI]]/(SUM(LER_01!$K$26:$K$27)+IF(LER_01!$D$10>=4,SUM(LER_01!$M$26:$M$27)))),3),"")) -> 0.173 | AK31: =IF(P31="","",IF(OR(P31="SOV",P31="SOB",P31="G0T",P31="G0B"),"",IF(AND(OR(P31="BSS",P31="BFS"),LER_01!$D$10<=2),15%,IF(AND(OR(P31="BSN",P31="BFN"),LER_01!$D$10>=4),100%,25%)))) | AM31: 320592.67 | AS31: =IF(COUNTBLANK(K31:AP31)=32,"",IF(OR(COUNTA(K31,L31,O31,P31,Q31,R31,S31,AC31,AH31,AI31,AM31)=11,AND(OR(P31="G1T",P31="G0T"),COUNTA(AH31)=1)),"","ERROR")) | AT31: =IF(ISBLANK(M31),"",IF(LEN(M31)=20,"","ERROR")) | AU31: =IF(ISBLANK(N31),"",IF(AND(LEFT(N31,3)="CHE",ISNUMBER(MID(N31,4,9)+0),LEN(N31)=12),"","ERROR")) | AV31: =IF(COUNTIF(O$19:O$169,O31)>1,"Duplicate","") | AW31: =IF(ISBLANK(O31),"",IF(ABS(AC31-SUM(U31,V31,W31,X31,Y31,Z31,AA31,AB31))<=0.5,"","ERROR")) | AX31: =IF(ISBLANK(O31),"",IF(AC31+SUM(AD31,AE31,AF31,AG31)>=AH31-0.5,"","ERROR")) | AY31: =IF(ISBLANK(O31),"",IF(AH31>=AI31-0.5,"","ERROR")) | AZ31: =IF(ISBLANK(O31),"",IF(AI31>=AN31-0.5,"","ERROR")) | BA31: =IF(ISBLANK(O31),"",IF(T31>=0,"","ERROR")) | BB31: =IF(ISBLANK(O31),"",IF(COUNTIF(AD31:AG31,">0")>0,"ERROR","")) | BC31: =IF(ISBLANK(O31),"",IF(ISBLANK(AO31),"",IF(AO31>='Delivery Note'!$H$5,IF(AO31<='Delivery Note'!$H$5+92,"","ERROR"),"ERROR"))) | BD31: =IF(COUNTBLANK(K31:AP31)=32,"",IF(AND(COUNTIF(P$19:P$169,"G0T")>0,COUNTIF(P$19:P$169,"G1T")>0),IF(AND(OR(P31="G0T",P31="G1T"),OR(ISBLANK(AH31),AH31<0)),"WARNING",""),"WARNING")) | BE31: =IF(ISBLANK(P31),"",IF(AND(OR(P31="OTH", P31="PDT"), ISBLANK(AP31)), "WARNING", ""))
E32: 32 | K32: COUNTERPARTY 14 | L32: CHE | O32: GROUP 14 | P32: FPS | Q32: No | R32: 64 | S32: IND | Y32: 286522.98 | AC32: 286522.98 | AG32: -286522.98 | AH32: 0 | AI32: 0 | AJ32: =IF(P32="","",IFERROR(ROUND(IF(OR(P32="G0B",P32="G0T"),Tabelle5[[#This Row],[AI]]/SUM(LER_01!$L$26:$L$27),Tabelle5[[#This Row],[AI]]/(SUM(LER_01!$K$26:$K$27)+IF(LER_01!$D$10>=4,SUM(LER_01!$M$26:$M$27)))),3),"")) -> 0 | AK32: =IF(P32="","",IF(OR(P32="SOV",P32="SOB",P32="G0T",P32="G0B"),"",IF(AND(OR(P32="BSS",P32="BFS"),LER_01!$D$10<=2),15%,IF(AND(OR(P32="BSN",P32="BFN"),LER_01!$D$10>=4),100%,25%)))) -> 0.25 | AM32: 0 | AS32: =IF(COUNTBLANK(K32:AP32)=32,"",IF(OR(COUNTA(K32,L32,O32,P32,Q32,R32,S32,AC32,AH32,AI32,AM32)=11,AND(OR(P32="G1T",P32="G0T"),COUNTA(AH32)=1)),"","ERROR")) | AT32: =IF(ISBLANK(M32),"",IF(LEN(M32)=20,"","ERROR")) | AU32: =IF(ISBLANK(N32),"",IF(AND(LEFT(N32,3)="CHE",ISNUMBER(MID(N32,4,9)+0),LEN(N32)=12),"","ERROR")) | AV32: =IF(COUNTIF(O$19:O$169,O32)>1,"Duplicate","") | AW32: =IF(ISBLANK(O32),"",IF(ABS(AC32-SUM(U32,V32,W32,X32,Y32,Z32,AA32,AB32))<=0.5,"","ERROR")) | AX32: =IF(ISBLANK(O32),"",IF(AC32+SUM(AD32,AE32,AF32,AG32)>=AH32-0.5,"","ERROR")) | AY32: =IF(ISBLANK(O32),"",IF(AH32>=AI32-0.5,"","ERROR")) | AZ32: =IF(ISBLANK(O32),"",IF(AI32>=AN32-0.5,"","ERROR")) | BA32: =IF(ISBLANK(O32),"",IF(T32>=0,"","ERROR")) | BB32: =IF(ISBLANK(O32),"",IF(COUNTIF(AD32:AG32,">0")>0,"ERROR","")) | BC32: =IF(ISBLANK(O32),"",IF(ISBLANK(AO32),"",IF(AO32>='Delivery Note'!$H$5,IF(AO32<='Delivery Note'!$H$5+92,"","ERROR"),"ERROR"))) | BD32: =IF(COUNTBLANK(K32:AP32)=32,"",IF(AND(COUNTIF(P$19:P$169,"G0T")>0,COUNTIF(P$19:P$169,"G1T")>0),IF(AND(OR(P32="G0T",P32="G1T"),OR(ISBLANK(AH32),AH32<0)),"WARNING",""),"WARNING")) | BE32: =IF(ISBLANK(P32),"",IF(AND(OR(P32="OTH", P32="PDT"), ISBLANK(AP32)), "WARNING", ""))
E33: 33 | K33: COUNTERPARTY 15 | L33: CHE | O33: GROUP 15 | P33: BFN | Q33: No | R33: 98 | S33: IND | Z33: 199913.24 | AA33: 75912.224 | AC33: 275825.46 | AF33: -195114.92 | AH33: 80710.535 | AI33: 80710.535 | AJ33: =IF(P33="","",IFERROR(ROUND(IF(OR(P33="G0B",P33="G0T"),Tabelle5[[#This Row],[AI]]/SUM(LER_01!$L$26:$L$27),Tabelle5[[#This Row],[AI]]/(SUM(LER_01!$K$26:$K$27)+IF(LER_01!$D$10>=4,SUM(LER_01!$M$26:$M$27)))),3),"")) -> 0.043 | AK33: =IF(P33="","",IF(OR(P33="SOV",P33="SOB",P33="G0T",P33="G0B"),"",IF(AND(OR(P33="BSS",P33="BFS"),LER_01!$D$10<=2),15%,IF(AND(OR(P33="BSN",P33="BFN"),LER_01!$D$10>=4),100%,25%)))) -> 0.25 | AM33: 80710.535 | AS33: =IF(COUNTBLANK(K33:AP33)=32,"",IF(OR(COUNTA(K33,L33,O33,P33,Q33,R33,S33,AC33,AH33,AI33,AM33)=11,AND(OR(P33="G1T",P33="G0T"),COUNTA(AH33)=1)),"","ERROR")) | AT33: =IF(ISBLANK(M33),"",IF(LEN(M33)=20,"","ERROR")) | AU33: =IF(ISBLANK(N33),"",IF(AND(LEFT(N33,3)="CHE",ISNUMBER(MID(N33,4,9)+0),LEN(N33)=12),"","ERROR")) | AV33: =IF(COUNTIF(O$19:O$169,O33)>1,"Duplicate","") | AW33: =IF(ISBLANK(O33),"",IF(ABS(AC33-SUM(U33,V33,W33,X33,Y33,Z33,AA33,AB33))<=0.5,"","ERROR")) | AX33: =IF(ISBLANK(O33),"",IF(AC33+SUM(AD33,AE33,AF33,AG33)>=AH33-0.5,"","ERROR")) | AY33: =IF(ISBLANK(O33),"",IF(AH33>=AI33-0.5,"","ERROR")) | AZ33: =IF(ISBLANK(O33),"",IF(AI33>=AN33-0.5,"","ERROR")) | BA33: =IF(ISBLANK(O33),"",IF(T33>=0,"","ERROR")) | BB33: =IF(ISBLANK(O33),"",IF(COUNTIF(AD33:AG33,">0")>0,"ERROR","")) | BC33: =IF(ISBLANK(O33),"",IF(ISBLANK(AO33),"",IF(AO33>='Delivery Note'!$H$5,IF(AO33<='Delivery Note'!$H$5+92,"","ERROR"),"ERROR"))) | BD33: =IF(COUNTBLANK(K33:AP33)=32,"",IF(AND(COUNTIF(P$19:P$169,"G0T")>0,COUNTIF(P$19:P$169,"G1T")>0),IF(AND(OR(P33="G0T",P33="G1T"),OR(ISBLANK(AH33),AH33<0)),"WARNING",""),"WARNING")) | BE33: =IF(ISBLANK(P33),"",IF(AND(OR(P33="OTH", P33="PDT"), ISBLANK(AP33)), "WARNING", ""))
E34: 34 | K34: COUNTERPARTY 16 | L34: CHE | O34: GROUP 16 | P34: BSS | Q34: No | R34: 64 | S34: CD | V34: 40157.393 | W34: 7051.916 | Y34: 15526.161 | Z34: 170398.08 | AA34: 49428.113 | AC34: 282561.66 | AH34: 282561.66 | AI34: 282561.66 | AJ34: =IF(P34="","",IFERROR(ROUND(IF(OR(P34="G0B",P34="G0T"),Tabelle5[[#This Row],[AI]]/SUM(LER_01!$L$26:$L$27),Tabelle5[[#This Row],[AI]]/(SUM(LER_01!$K$26:$K$27)+IF(LER_01!$D$10>=4,SUM(LER_01!$M$26:$M$27)))),3),"")) -> 0.152 | AK34: =IF(P34="","",IF(OR(P34="SOV",P34="SOB",P34="G0T",P34="G0B"),"",IF(AND(OR(P34="BSS",P34="BFS"),LER_01!$D$10<=2),15%,IF(AND(OR(P34="BSN",P34="BFN"),LER_01!$D$10>=4),100%,25%)))) -> 0.25 | AM34: 282561.66 | AS34: =IF(COUNTBLANK(K34:AP34)=32,"",IF(OR(COUNTA(K34,L34,O34,P34,Q34,R34,S34,AC34,AH34,AI34,AM34)=11,AND(OR(P34="G1T",P34="G0T"),COUNTA(AH34)=1)),"","ERROR")) | AT34: =IF(ISBLANK(M34),"",IF(LEN(M34)=20,"","ERROR")) | AU34: =IF(ISBLANK(N34),"",IF(AND(LEFT(N34,3)="CHE",ISNUMBER(MID(N34,4,9)+0),LEN(N34)=12),"","ERROR")) | AV34: =IF(COUNTIF(O$19:O$169,O34)>1,"Duplicate","") | AW34: =IF(ISBLANK(O34),"",IF(ABS(AC34-SUM(U34,V34,W34,X34,Y34,Z34,AA34,AB34))<=0.5,"","ERROR")) | AX34: =IF(ISBLANK(O34),"",IF(AC34+SUM(AD34,AE34,AF34,AG34)>=AH34-0.5,"","ERROR")) | AY34: =IF(ISBLANK(O34),"",IF(AH34>=AI34-0.5,"","ERROR")) | AZ34: =IF(ISBLANK(O34),"",IF(AI34>=AN34-0.5,"","ERROR")) | BA34: =IF(ISBLANK(O34),"",IF(T34>=0,"","ERROR")) | BB34: =IF(ISBLANK(O34),"",IF(COUNTIF(AD34:AG34,">0")>0,"ERROR","")) | BC34: =IF(ISBLANK(O34),"",IF(ISBLANK(AO34),"",IF(AO34>='Delivery Note'!$H$5,IF(AO34<='Delivery Note'!$H$5+92,"","ERROR"),"ERROR"))) | BD34: =IF(COUNTBLANK(K34:AP34)=32,"",IF(AND(COUNTIF(P$19:P$169,"G0T")>0,COUNTIF(P$19:P$169,"G1T")>0),IF(AND(OR(P34="G0T",P34="G1T"),OR(ISBLANK(AH34),AH34<0)),"WARNING",""),"WARNING")) | BE34: =IF(ISBLANK(P34),"",IF(AND(OR(P34="OTH", P34="PDT"), ISBLANK(AP34)), "WARNING", ""))
E35: 35 | K35: COUNTERPARTY 17 | L35: CHE | O35: GROUP 17 | P35: SOV | Q35: No | R35: 84 | S35: IND | Y35: 251018.4 | AA35: 14968.054 | AC35: 265986.45 | AH35: 265986.45 | AI35: 265986.45 | AJ35: =IF(P35="","",IFERROR(ROUND(IF(OR(P35="G0B",P35="G0T"),Tabelle5[[#This Row],[AI]]/SUM(LER_01!$L$26:$L$27),Tabelle5[[#This Row],[AI]]/(SUM(LER_01!$K$26:$K$27)+IF(LER_01!$D$10>=4,SUM(LER_01!$M$26:$M$27)))),3),"")) -> 0.143 | AK35: =IF(P35="","",IF(OR(P35="SOV",P35="SOB",P35="G0T",P35="G0B"),"",IF(AND(OR(P35="BSS",P35="BFS"),LER_01!$D$10<=2),15%,IF(AND(OR(P35="BSN",P35="BFN"),LER_01!$D$10>=4),100%,25%)))) | AM35: 265986.45 | AS35: =IF(COUNTBLANK(K35:AP35)=32,"",IF(OR(COUNTA(K35,L35,O35,P35,Q35,R35,S35,AC35,AH35,AI35,AM35)=11,AND(OR(P35="G1T",P35="G0T"),COUNTA(AH35)=1)),"","ERROR")) | AT35: =IF(ISBLANK(M35),"",IF(LEN(M35)=20,"","ERROR")) | AU35: =IF(ISBLANK(N35),"",IF(AND(LEFT(N35,3)="CHE",ISNUMBER(MID(N35,4,9)+0),LEN(N35)=12),"","ERROR")) | AV35: =IF(COUNTIF(O$19:O$169,O35)>1,"Duplicate","") | AW35: =IF(ISBLANK(O35),"",IF(ABS(AC35-SUM(U35,V35,W35,X35,Y35,Z35,AA35,AB35))<=0.5,"","ERROR")) | AX35: =IF(ISBLANK(O35),"",IF(AC35+SUM(AD35,AE35,AF35,AG35)>=AH35-0.5,"","ERROR")) | AY35: =IF(ISBLANK(O35),"",IF(AH35>=AI35-0.5,"","ERROR")) | AZ35: =IF(ISBLANK(O35),"",IF(AI35>=AN35-0.5,"","ERROR")) | BA35: =IF(ISBLANK(O35),"",IF(T35>=0,"","ERROR")) | BB35: =IF(ISBLANK(O35),"",IF(COUNTIF(AD35:AG35,">0")>0,"ERROR","")) | BC35: =IF(ISBLANK(O35),"",IF(ISBLANK(AO35),"",IF(AO35>='Delivery Note'!$H$5,IF(AO35<='Delivery Note'!$H$5+92,"","ERROR"),"ERROR"))) | BD35: =IF(COUNTBLANK(K35:AP35)=32,"",IF(AND(COUNTIF(P$19:P$169,"G0T")>0,COUNTIF(P$19:P$169,"G1T")>0),IF(AND(OR(P35="G0T",P35="G1T"),OR(ISBLANK(AH35),AH35<0)),"WARNING",""),"WARNING")) | BE35: =IF(ISBLANK(P35),"",IF(AND(OR(P35="OTH", P35="PDT"), ISBLANK(AP35)), "WARNING", ""))
E36: 36 | K36: COUNTERPARTY 18 | L36: CHE | O36: GROUP 18 | P36: BFN | Q36: No | R36: 64 | S36: IND | Z36: 194291.61 | AA36: 63416.816 | AC36: 257708.42 | AF36: -178986.02 | AH36: 78722.405 | AI36: 78722.405 | AJ36: =IF(P36="","",IFERROR(ROUND(IF(OR(P36="G0B",P36="G0T"),Tabelle5[[#This Row],[AI]]/SUM(LER_01!$L$26:$L$27),Tabelle5[[#This Row],[AI]]/(SUM(LER_01!$K$26:$K$27)+IF(LER_01!$D$10>=4,SUM(LER_01!$M$26:$M$27)))),3),"")) -> 0.042 | AK36: =IF(P36="","",IF(OR(P36="SOV",P36="SOB",P36="G0T",P36="G0B"),"",IF(AND(OR(P36="BSS",P36="BFS"),LER_01!$D$10<=2),15%,IF(AND(OR(P36="BSN",P36="BFN"),LER_01!$D$10>=4),100%,25%)))) -> 0.25 | AM36: 78722.405 | AS36: =IF(COUNTBLANK(K36:AP36)=32,"",IF(OR(COUNTA(K36,L36,O36,P36,Q36,R36,S36,AC36,AH36,AI36,AM36)=11,AND(OR(P36="G1T",P36="G0T"),COUNTA(AH36)=1)),"","ERROR")) | AT36: =IF(ISBLANK(M36),"",IF(LEN(M36)=20,"","ERROR")) | AU36: =IF(ISBLANK(N36),"",IF(AND(LEFT(N36,3)="CHE",ISNUMBER(MID(N36,4,9)+0),LEN(N36)=12),"","ERROR")) | AV36: =IF(COUNTIF(O$19:O$169,O36)>1,"Duplicate","") | AW36: =IF(ISBLANK(O36),"",IF(ABS(AC36-SUM(U36,V36,W36,X36,Y36,Z36,AA36,AB36))<=0.5,"","ERROR")) | AX36: =IF(ISBLANK(O36),"",IF(AC36+SUM(AD36,AE36,AF36,AG36)>=AH36-0.5,"","ERROR")) | AY36: =IF(ISBLANK(O36),"",IF(AH36>=AI36-0.5,"","ERROR")) | AZ36: =IF(ISBLANK(O36),"",IF(AI36>=AN36-0.5,"","ERROR")) | BA36: =IF(ISBLANK(O36),"",IF(T36>=0,"","ERROR")) | BB36: =IF(ISBLANK(O36),"",IF(COUNTIF(AD36:AG36,">0")>0,"ERROR","")) | BC36: =IF(ISBLANK(O36),"",IF(ISBLANK(AO36),"",IF(AO36>='Delivery Note'!$H$5,IF(AO36<='Delivery Note'!$H$5+92,"","ERROR"),"ERROR"))) | BD36: =IF(COUNTBLANK(K36:AP36)=32,"",IF(AND(COUNTIF(P$19:P$169,"G0T")>0,COUNTIF(P$19:P$169,"G1T")>0),IF(AND(OR(P36="G0T",P36="G1T"),OR(ISBLANK(AH36),AH36<0)),"WARNING",""),"WARNING")) | BE36: =IF(ISBLANK(P36),"",IF(AND(OR(P36="OTH", P36="PDT"), ISBLANK(AP36)), "WARNING", ""))
E37: 37 | K37: COUNTERPARTY 19 | L37: CHE | O37: GROUP 19 | P37: FPS | Q37: No | R37: 64 | S37: IND | Y37: 254421.29 | AC37: 254421.29 | AG37: -254421.29 | AH37: 0 | AI37: 0 | AJ37: =IF(P37="","",IFERROR(ROUND(IF(OR(P37="G0B",P37="G0T"),Tabelle5[[#This Row],[AI]]/SUM(LER_01!$L$26:$L$27),Tabelle5[[#This Row],[AI]]/(SUM(LER_01!$K$26:$K$27)+IF(LER_01!$D$10>=4,SUM(LER_01!$M$26:$M$27)))),3),"")) -> 0 | AK37: =IF(P37="","",IF(OR(P37="SOV",P37="SOB",P37="G0T",P37="G0B"),"",IF(AND(OR(P37="BSS",P37="BFS"),LER_01!$D$10<=2),15%,IF(AND(OR(P37="BSN",P37="BFN"),LER_01!$D$10>=4),100%,25%)))) -> 0.25 | AM37: 0 | AS37: =IF(COUNTBLANK(K37:AP37)=32,"",IF(OR(COUNTA(K37,L37,O37,P37,Q37,R37,S37,AC37,AH37,AI37,AM37)=11,AND(OR(P37="G1T",P37="G0T"),COUNTA(AH37)=1)),"","ERROR")) | AT37: =IF(ISBLANK(M37),"",IF(LEN(M37)=20,"","ERROR")) | AU37: =IF(ISBLANK(N37),"",IF(AND(LEFT(N37,3)="CHE",ISNUMBER(MID(N37,4,9)+0),LEN(N37)=12),"","ERROR")) | AV37: =IF(COUNTIF(O$19:O$169,O37)>1,"Duplicate","") | AW37: =IF(ISBLANK(O37),"",IF(ABS(AC37-SUM(U37,V37,W37,X37,Y37,Z37,AA37,AB37))<=0.5,"","ERROR")) | AX37: =IF(ISBLANK(O37),"",IF(AC37+SUM(AD37,AE37,AF37,AG37)>=AH37-0.5,"","ERROR")) | AY37: =IF(ISBLANK(O37),"",IF(AH37>=AI37-0.5,"","ERROR")) | AZ37: =IF(ISBLANK(O37),"",IF(AI37>=AN37-0.5,"","ERROR")) | BA37: =IF(ISBLANK(O37),"",IF(T37>=0,"","ERROR")) | BB37: =IF(ISBLANK(O37),"",IF(COUNTIF(AD37:AG37,">0")>0,"ERROR","")) | BC37: =IF(ISBLANK(O37),"",IF(ISBLANK(AO37),"",IF(AO37>='Delivery Note'!$H$5,IF(AO37<='Delivery Note'!$H$5+92,"","ERROR"),"ERROR"))) | BD37: =IF(COUNTBLANK(K37:AP37)=32,"",IF(AND(COUNTIF(P$19:P$169,"G0T")>0,COUNTIF(P$19:P$169,"G1T")>0),IF(AND(OR(P37="G0T",P37="G1T"),OR(ISBLANK(AH37),AH37<0)),"WARNING",""),"WARNING")) | BE37: =IF(ISBLANK(P37),"",IF(AND(OR(P37="OTH", P37="PDT"), ISBLANK(AP37)), "WARNING", ""))
E38: 38 | K38: COUNTERPARTY 20 | L38: CHE | O38: GROUP 20 | P38: SOV | Q38: No | R38: 84 | S38: IND | Y38: 34766.902 | AA38: 3078.3285 | AB38: 205307.01 | AC38: 243152.24 | AH38: 243152.24 | AI38: 243152.24 | AJ38: =IF(P38="","",IFERROR(ROUND(IF(OR(P38="G0B",P38="G0T"),Tabelle5[[#This Row],[AI]]/SUM(LER_01!$L$26:$L$27),Tabelle5[[#This Row],[AI]]/(SUM(LER_01!$K$26:$K$27)+IF(LER_01!$D$10>=4,SUM(LER_01!$M$26:$M$27)))),3),"")) -> 0.131 | AK38: =IF(P38="","",IF(OR(P38="SOV",P38="SOB",P38="G0T",P38="G0B"),"",IF(AND(OR(P38="BSS",P38="BFS"),LER_01!$D$10<=2),15%,IF(AND(OR(P38="BSN",P38="BFN"),LER_01!$D$10>=4),100%,25%)))) | AM38: 243152.24 | AS38: =IF(COUNTBLANK(K38:AP38)=32,"",IF(OR(COUNTA(K38,L38,O38,P38,Q38,R38,S38,AC38,AH38,AI38,AM38)=11,AND(OR(P38="G1T",P38="G0T"),COUNTA(AH38)=1)),"","ERROR")) | AT38: =IF(ISBLANK(M38),"",IF(LEN(M38)=20,"","ERROR")) | AU38: =IF(ISBLANK(N38),"",IF(AND(LEFT(N38,3)="CHE",ISNUMBER(MID(N38,4,9)+0),LEN(N38)=12),"","ERROR")) | AV38: =IF(COUNTIF(O$19:O$169,O38)>1,"Duplicate","") | AW38: =IF(ISBLANK(O38),"",IF(ABS(AC38-SUM(U38,V38,W38,X38,Y38,Z38,AA38,AB38))<=0.5,"","ERROR")) | AX38: =IF(ISBLANK(O38),"",IF(AC38+SUM(AD38,AE38,AF38,AG38)>=AH38-0.5,"","ERROR")) | AY38: =IF(ISBLANK(O38),"",IF(AH38>=AI38-0.5,"","ERROR")) | AZ38: =IF(ISBLANK(O38),"",IF(AI38>=AN38-0.5,"","ERROR")) | BA38: =IF(ISBLANK(O38),"",IF(T38>=0,"","ERROR")) | BB38: =IF(ISBLANK(O38),"",IF(COUNTIF(AD38:AG38,">0")>0,"ERROR","")) | BC38: =IF(ISBLANK(O38),"",IF(ISBLANK(AO38),"",IF(AO38>='Delivery Note'!$H$5,IF(AO38<='Delivery Note'!$H$5+92,"","ERROR"),"ERROR"))) | BD38: =IF(COUNTBLANK(K38:AP38)=32,"",IF(AND(COUNTIF(P$19:P$169,"G0T")>0,COUNTIF(P$19:P$169,"G1T")>0),IF(AND(OR(P38="G0T",P38="G1T"),OR(ISBLANK(AH38),AH38<0)),"WARNING",""),"WARNING")) | BE38: =IF(ISBLANK(P38),"",IF(AND(OR(P38="OTH", P38="PDT"), ISBLANK(AP38)), "WARNING", ""))
E39: 39 | K39: COUNTERPARTY 21 | L39: CHE | O39: GROUP 21 | P39: NFC | Q39: No | R39: 33 | S39: IND | V39: 11.45361 | W39: 237123.09 | AC39: 237134.54 | AF39: -237123.09 | AH39: 11.45361 | AI39: 11.45361 | AJ39: =IF(P39="","",IFERROR(ROUND(IF(OR(P39="G0B",P39="G0T"),Tabelle5[[#This Row],[AI]]/SUM(LER_01!$L$26:$L$27),Tabelle5[[#This Row],[AI]]/(SUM(LER_01!$K$26:$K$27)+IF(LER_01!$D$10>=4,SUM(LER_01!$M$26:$M$27)))),3),"")) -> 0 | AK39: =IF(P39="","",IF(OR(P39="SOV",P39="SOB",P39="G0T",P39="G0B"),"",IF(AND(OR(P39="BSS",P39="BFS"),LER_01!$D$10<=2),15%,IF(AND(OR(P39="BSN",P39="BFN"),LER_01!$D$10>=4),100%,25%)))) -> 0.25 | AM39: 11.45361 | AS39: =IF(COUNTBLANK(K39:AP39)=32,"",IF(OR(COUNTA(K39,L39,O39,P39,Q39,R39,S39,AC39,AH39,AI39,AM39)=11,AND(OR(P39="G1T",P39="G0T"),COUNTA(AH39)=1)),"","ERROR")) | AT39: =IF(ISBLANK(M39),"",IF(LEN(M39)=20,"","ERROR")) | AU39: =IF(ISBLANK(N39),"",IF(AND(LEFT(N39,3)="CHE",ISNUMBER(MID(N39,4,9)+0),LEN(N39)=12),"","ERROR")) | AV39: =IF(COUNTIF(O$19:O$169,O39)>1,"Duplicate","") | AW39: =IF(ISBLANK(O39),"",IF(ABS(AC39-SUM(U39,V39,W39,X39,Y39,Z39,AA39,AB39))<=0.5,"","ERROR")) | AX39: =IF(ISBLANK(O39),"",IF(AC39+SUM(AD39,AE39,AF39,AG39)>=AH39-0.5,"","ERROR")) | AY39: =IF(ISBLANK(O39),"",IF(AH39>=AI39-0.5,"","ERROR")) | AZ39: =IF(ISBLANK(O39),"",IF(AI39>=AN39-0.5,"","ERROR")) | BA39: =IF(ISBLANK(O39),"",IF(T39>=0,"","ERROR")) | BB39: =IF(ISBLANK(O39),"",IF(COUNTIF(AD39:AG39,">0")>0,"ERROR","")) | BC39: =IF(ISBLANK(O39),"",IF(ISBLANK(AO39),"",IF(AO39>='Delivery Note'!$H$5,IF(AO39<='Delivery Note'!$H$5+92,"","ERROR"),"ERROR"))) | BD39: =IF(COUNTBLANK(K39:AP39)=32,"",IF(AND(COUNTIF(P$19:P$169,"G0T")>0,COUNTIF(P$19:P$169,"G1T")>0),IF(AND(OR(P39="G0T",P39="G1T"),OR(ISBLANK(AH39),AH39<0)),"WARNING",""),"WARNING")) | BE39: =IF(ISBLANK(P39),"",IF(AND(OR(P39="OTH", P39="PDT"), ISBLANK(AP39)), "WARNING", ""))
E40: 40 | K40: COUNTERPARTY 22 | L40: CHE | O40: GROUP 22 | P40: FPS | Q40: No | R40: 64 | S40: IND | Y40: 203550.42 | AC40: 203550.42 | AG40: -203550.42 | AH40: 0 | AI40: 0 | AJ40: =IF(P40="","",IFERROR(ROUND(IF(OR(P40="G0B",P40="G0T"),Tabelle5[[#This Row],[AI]]/SUM(LER_01!$L$26:$L$27),Tabelle5[[#This Row],[AI]]/(SUM(LER_01!$K$26:$K$27)+IF(LER_01!$D$10>=4,SUM(LER_01!$M$26:$M$27)))),3),"")) -> 0 | AK40: =IF(P40="","",IF(OR(P40="SOV",P40="SOB",P40="G0T",P40="G0B"),"",IF(AND(OR(P40="BSS",P40="BFS"),LER_01!$D$10<=2),15%,IF(AND(OR(P40="BSN",P40="BFN"),LER_01!$D$10>=4),100%,25%)))) -> 0.25 | AM40: 0 | AS40: =IF(COUNTBLANK(K40:AP40)=32,"",IF(OR(COUNTA(K40,L40,O40,P40,Q40,R40,S40,AC40,AH40,AI40,AM40)=11,AND(OR(P40="G1T",P40="G0T"),COUNTA(AH40)=1)),"","ERROR")) | AT40: =IF(ISBLANK(M40),"",IF(LEN(M40)=20,"","ERROR")) | AU40: =IF(ISBLANK(N40),"",IF(AND(LEFT(N40,3)="CHE",ISNUMBER(MID(N40,4,9)+0),LEN(N40)=12),"","ERROR")) | AV40: =IF(COUNTIF(O$19:O$169,O40)>1,"Duplicate","") | AW40: =IF(ISBLANK(O40),"",IF(ABS(AC40-SUM(U40,V40,W40,X40,Y40,Z40,AA40,AB40))<=0.5,"","ERROR")) | AX40: =IF(ISBLANK(O40),"",IF(AC40+SUM(AD40,AE40,AF40,AG40)>=AH40-0.5,"","ERROR")) | AY40: =IF(ISBLANK(O40),"",IF(AH40>=AI40-0.5,"","ERROR")) | AZ40: =IF(ISBLANK(O40),"",IF(AI40>=AN40-0.5,"","ERROR")) | BA40: =IF(ISBLANK(O40),"",IF(T40>=0,"","ERROR")) | BB40: =IF(ISBLANK(O40),"",IF(COUNTIF(AD40:AG40,">0")>0,"ERROR","")) | BC40: =IF(ISBLANK(O40),"",IF(ISBLANK(AO40),"",IF(AO40>='Delivery Note'!$H$5,IF(AO40<='Delivery Note'!$H$5+92,"","ERROR"),"ERROR"))) | BD40: =IF(COUNTBLANK(K40:AP40)=32,"",IF(AND(COUNTIF(P$19:P$169,"G0T")>0,COUNTIF(P$19:P$169,"G1T")>0),IF(AND(OR(P40="G0T",P40="G1T"),OR(ISBLANK(AH40),AH40<0)),"WARNING",""),"WARNING")) | BE40: =IF(ISBLANK(P40),"",IF(AND(OR(P40="OTH", P40="PDT"), ISBLANK(AP40)), "WARNING", ""))
E41: 41 | K41: COUNTERPARTY 23 | L41: CHE | O41: GROUP 23 | P41: BFN | Q41: No | R41: 64 | S41: IND | Y41: 202270.68 | AA41: 366.05491 | AC41: 202636.74 | AH41: 202636.74 | AI41: 202636.74 | AJ41: =IF(P41="","",IFERROR(ROUND(IF(OR(P41="G0B",P41="G0T"),Tabelle5[[#This Row],[AI]]/SUM(LER_01!$L$26:$L$27),Tabelle5[[#This Row],[AI]]/(SUM(LER_01!$K$26:$K$27)+IF(LER_01!$D$10>=4,SUM(LER_01!$M$26:$M$27)))),3),"")) -> 0.109 | AK41: =IF(P41="","",IF(OR(P41="SOV",P41="SOB",P41="G0T",P41="G0B"),"",IF(AND(OR(P41="BSS",P41="BFS"),LER_01!$D$10<=2),15%,IF(AND(OR(P41="BSN",P41="BFN"),LER_01!$D$10>=4),100%,25%)))) -> 0.25 | AM41: 202636.74 | AS41: =IF(COUNTBLANK(K41:AP41)=32,"",IF(OR(COUNTA(K41,L41,O41,P41,Q41,R41,S41,AC41,AH41,AI41,AM41)=11,AND(OR(P41="G1T",P41="G0T"),COUNTA(AH41)=1)),"","ERROR")) | AT41: =IF(ISBLANK(M41),"",IF(LEN(M41)=20,"","ERROR")) | AU41: =IF(ISBLANK(N41),"",IF(AND(LEFT(N41,3)="CHE",ISNUMBER(MID(N41,4,9)+0),LEN(N41)=12),"","ERROR")) | AV41: =IF(COUNTIF(O$19:O$169,O41)>1,"Duplicate","") | AW41: =IF(ISBLANK(O41),"",IF(ABS(AC41-SUM(U41,V41,W41,X41,Y41,Z41,AA41,AB41))<=0.5,"","ERROR")) | AX41: =IF(ISBLANK(O41),"",IF(AC41+SUM(AD41,AE41,AF41,AG41)>=AH41-0.5,"","ERROR")) | AY41: =IF(ISBLANK(O41),"",IF(AH41>=AI41-0.5,"","ERROR")) | AZ41: =IF(ISBLANK(O41),"",IF(AI41>=AN41-0.5,"","ERROR")) | BA41: =IF(ISBLANK(O41),"",IF(T41>=0,"","ERROR")) | BB41: =IF(ISBLANK(O41),"",IF(COUNTIF(AD41:AG41,">0")>0,"ERROR","")) | BC41: =IF(ISBLANK(O41),"",IF(ISBLANK(AO41),"",IF(AO41>='Delivery Note'!$H$5,IF(AO41<='Delivery Note'!$H$5+92,"","ERROR"),"ERROR"))) | BD41: =IF(COUNTBLANK(K41:AP41)=32,"",IF(AND(COUNTIF(P$19:P$169,"G0T")>0,COUNTIF(P$19:P$169,"G1T")>0),IF(AND(OR(P41="G0T",P41="G1T"),OR(ISBLANK(AH41),AH41<0)),"WARNING",""),"WARNING")) | BE41: =IF(ISBLANK(P41),"",IF(AND(OR(P41="OTH", P41="PDT"), ISBLANK(AP41)), "WARNING", ""))
E42: 42 | K42: COUNTERPARTY 24 | L42: CHE | O42: GROUP 24 | P42: BFN | Q42: No | R42: 64 | S42: IND | Z42: 198339.51 | AC42: 198339.51 | AF42: -198339.51 | AH42: 0 | AI42: 0 | AJ42: =IF(P42="","",IFERROR(ROUND(IF(OR(P42="G0B",P42="G0T"),Tabelle5[[#This Row],[AI]]/SUM(LER_01!$L$26:$L$27),Tabelle5[[#This Row],[AI]]/(SUM(LER_01!$K$26:$K$27)+IF(LER_01!$D$10>=4,SUM(LER_01!$M$26:$M$27)))),3),"")) -> 0 | AK42: =IF(P42="","",IF(OR(P42="SOV",P42="SOB",P42="G0T",P42="G0B"),"",IF(AND(OR(P42="BSS",P42="BFS"),LER_01!$D$10<=2),15%,IF(AND(OR(P42="BSN",P42="BFN"),LER_01!$D$10>=4),100%,25%)))) -> 0.25 | AM42: 0 | AS42: =IF(COUNTBLANK(K42:AP42)=32,"",IF(OR(COUNTA(K42,L42,O42,P42,Q42,R42,S42,AC42,AH42,AI42,AM42)=11,AND(OR(P42="G1T",P42="G0T"),COUNTA(AH42)=1)),"","ERROR")) | AT42: =IF(ISBLANK(M42),"",IF(LEN(M42)=20,"","ERROR")) | AU42: =IF(ISBLANK(N42),"",IF(AND(LEFT(N42,3)="CHE",ISNUMBER(MID(N42,4,9)+0),LEN(N42)=12),"","ERROR")) | AV42: =IF(COUNTIF(O$19:O$169,O42)>1,"Duplicate","") | AW42: =IF(ISBLANK(O42),"",IF(ABS(AC42-SUM(U42,V42,W42,X42,Y42,Z42,AA42,AB42))<=0.5,"","ERROR")) | AX42: =IF(ISBLANK(O42),"",IF(AC42+SUM(AD42,AE42,AF42,AG42)>=AH42-0.5,"","ERROR")) | AY42: =IF(ISBLANK(O42),"",IF(AH42>=AI42-0.5,"","ERROR")) | AZ42: =IF(ISBLANK(O42),"",IF(AI42>=AN42-0.5,"","ERROR")) | BA42: =IF(ISBLANK(O42),"",IF(T42>=0,"","ERROR")) | BB42: =IF(ISBLANK(O42),"",IF(COUNTIF(AD42:AG42,">0")>0,"ERROR","")) | BC42: =IF(ISBLANK(O42),"",IF(ISBLANK(AO42),"",IF(AO42>='Delivery Note'!$H$5,IF(AO42<='Delivery Note'!$H$5+92,"","ERROR"),"ERROR"))) | BD42: =IF(COUNTBLANK(K42:AP42)=32,"",IF(AND(COUNTIF(P$19:P$169,"G0T")>0,COUNTIF(P$19:P$169,"G1T")>0),IF(AND(OR(P42="G0T",P42="G1T"),OR(ISBLANK(AH42),AH42<0)),"WARNING",""),"WARNING")) | BE42: =IF(ISBLANK(P42),"",IF(AND(OR(P42="OTH", P42="PDT"), ISBLANK(AP42)), "WARNING", ""))
E43: 43 | K43: COUNTERPARTY 25 | L43: CHE | O43: GROUP 25 | P43: BFN | Q43: No | R43: 64 | S43: IND | Y43: 196261.74 | AC43: 196261.74 | AH43: 196261.74 | AI43: 196261.74 | AJ43: =IF(P43="","",IFERROR(ROUND(IF(OR(P43="G0B",P43="G0T"),Tabelle5[[#This Row],[AI]]/SUM(LER_01!$L$26:$L$27),Tabelle5[[#This Row],[AI]]/(SUM(LER_01!$K$26:$K$27)+IF(LER_01!$D$10>=4,SUM(LER_01!$M$26:$M$27)))),3),"")) -> 0.106 | AK43: =IF(P43="","",IF(OR(P43="SOV",P43="SOB",P43="G0T",P43="G0B"),"",IF(AND(OR(P43="BSS",P43="BFS"),LER_01!$D$10<=2),15%,IF(AND(OR(P43="BSN",P43="BFN"),LER_01!$D$10>=4),100%,25%)))) -> 0.25 | AM43: 196261.74 | AS43: =IF(COUNTBLANK(K43:AP43)=32,"",IF(OR(COUNTA(K43,L43,O43,P43,Q43,R43,S43,AC43,AH43,AI43,AM43)=11,AND(OR(P43="G1T",P43="G0T"),COUNTA(AH43)=1)),"","ERROR")) | AT43: =IF(ISBLANK(M43),"",IF(LEN(M43)=20,"","ERROR")) | AU43: =IF(ISBLANK(N43),"",IF(AND(LEFT(N43,3)="CHE",ISNUMBER(MID(N43,4,9)+0),LEN(N43)=12),"","ERROR")) | AV43: =IF(COUNTIF(O$19:O$169,O43)>1,"Duplicate","") | AW43: =IF(ISBLANK(O43),"",IF(ABS(AC43-SUM(U43,V43,W43,X43,Y43,Z43,AA43,AB43))<=0.5,"","ERROR")) | AX43: =IF(ISBLANK(O43),"",IF(AC43+SUM(AD43,AE43,AF43,AG43)>=AH43-0.5,"","ERROR")) | AY43: =IF(ISBLANK(O43),"",IF(AH43>=AI43-0.5,"","ERROR")) | AZ43: =IF(ISBLANK(O43),"",IF(AI43>=AN43-0.5,"","ERROR")) | BA43: =IF(ISBLANK(O43),"",IF(T43>=0,"","ERROR")) | BB43: =IF(ISBLANK(O43),"",IF(COUNTIF(AD43:AG43,">0")>0,"ERROR","")) | BC43: =IF(ISBLANK(O43),"",IF(ISBLANK(AO43),"",IF(AO43>='Delivery Note'!$H$5,IF(AO43<='Delivery Note'!$H$5+92,"","ERROR"),"ERROR"))) | BD43: =IF(COUNTBLANK(K43:AP43)=32,"",IF(AND(COUNTIF(P$19:P$169,"G0T")>0,COUNTIF(P$19:P$169,"G1T")>0),IF(AND(OR(P43="G0T",P43="G1T"),OR(ISBLANK(AH43),AH43<0)),"WARNING",""),"WARNING")) | BE43: =IF(ISBLANK(P43),"",IF(AND(OR(P43="OTH", P43="PDT"), ISBLANK(AP43)), "WARNING", ""))
E44: 44 | K44: COUNTERPARTY 26 | L44: CHE | O44: GROUP 26 | P44: G0T | Q44: Yes | R44: 64 | S44: IND | V44: 329.38954 | Z44: 225.62375 | AC44: 555.01329 | AH44: 555.01329 | AI44: 555.01329 | AJ44: =IF(P44="","",IFERROR(ROUND(IF(OR(P44="G0B",P44="G0T"),Tabelle5[[#This Row],[AI]]/SUM(LER_01!$L$26:$L$27),Tabelle5[[#This Row],[AI]]/(SUM(LER_01!$K$26:$K$27)+IF(LER_01!$D$10>=4,SUM(LER_01!$M$26:$M$27)))),3),"")) -> 0 | AK44: =IF(P44="","",IF(OR(P44="SOV",P44="SOB",P44="G0T",P44="G0B"),"",IF(AND(OR(P44="BSS",P44="BFS"),LER_01!$D$10<=2),15%,IF(AND(OR(P44="BSN",P44="BFN"),LER_01!$D$10>=4),100%,25%)))) | AM44: 555.01329 | AS44: =IF(COUNTBLANK(K44:AP44)=32,"",IF(OR(COUNTA(K44,L44,O44,P44,Q44,R44,S44,AC44,AH44,AI44,AM44)=11,AND(OR(P44="G1T",P44="G0T"),COUNTA(AH44)=1)),"","ERROR")) | AT44: =IF(ISBLANK(M44),"",IF(LEN(M44)=20,"","ERROR")) | AU44: =IF(ISBLANK(N44),"",IF(AND(LEFT(N44,3)="CHE",ISNUMBER(MID(N44,4,9)+0),LEN(N44)=12),"","ERROR")) | AV44: =IF(COUNTIF(O$19:O$169,O44)>1,"Duplicate","") | AW44: =IF(ISBLANK(O44),"",IF(ABS(AC44-SUM(U44,V44,W44,X44,Y44,Z44,AA44,AB44))<=0.5,"","ERROR")) | AX44: =IF(ISBLANK(O44),"",IF(AC44+SUM(AD44,AE44,AF44,AG44)>=AH44-0.5,"","ERROR")) | AY44: =IF(ISBLANK(O44),"",IF(AH44>=AI44-0.5,"","ERROR")) | AZ44: =IF(ISBLANK(O44),"",IF(AI44>=AN44-0.5,"","ERROR")) | BA44: =IF(ISBLANK(O44),"",IF(T44>=0,"","ERROR")) | BB44: =IF(ISBLANK(O44),"",IF(COUNTIF(AD44:AG44,">0")>0,"ERROR","")) | BC44: =IF(ISBLANK(O44),"",IF(ISBLANK(AO44),"",IF(AO44>='Delivery Note'!$H$5,IF(AO44<='Delivery Note'!$H$5+92,"","ERROR"),"ERROR"))) | BD44: =IF(COUNTBLANK(K44:AP44)=32,"",IF(AND(COUNTIF(P$19:P$169,"G0T")>0,COUNTIF(P$19:P$169,"G1T")>0),IF(AND(OR(P44="G0T",P44="G1T"),OR(ISBLANK(AH44),AH44<0)),"WARNING",""),"WARNING")) | BE44: =IF(ISBLANK(P44),"",IF(AND(OR(P44="OTH", P44="PDT"), ISBLANK(AP44)), "WARNING", ""))
E45: 45 | K45: COUNTERPARTY 27 | L45: CHE | O45: GROUP 27 | P45: G0B | Q45: Yes | R45: 64 | S45: IND | V45: 329.38954 | Z45: 225.62375 | AC45: 555.01329 | AH45: 555.01329 | AI45: 555.01329 | AJ45: =IF(P45="","",IFERROR(ROUND(IF(OR(P45="G0B",P45="G0T"),Tabelle5[[#This Row],[AI]]/SUM(LER_01!$L$26:$L$27),Tabelle5[[#This Row],[AI]]/(SUM(LER_01!$K$26:$K$27)+IF(LER_01!$D$10>=4,SUM(LER_01!$M$26:$M$27)))),3),"")) -> 0 | AK45: =IF(P45="","",IF(OR(P45="SOV",P45="SOB",P45="G0T",P45="G0B"),"",IF(AND(OR(P45="BSS",P45="BFS"),LER_01!$D$10<=2),15%,IF(AND(OR(P45="BSN",P45="BFN"),LER_01!$D$10>=4),100%,25%)))) | AM45: 555.01329 | AS45: =IF(COUNTBLANK(K45:AP45)=32,"",IF(OR(COUNTA(K45,L45,O45,P45,Q45,R45,S45,AC45,AH45,AI45,AM45)=11,AND(OR(P45="G1T",P45="G0T"),COUNTA(AH45)=1)),"","ERROR")) | AT45: =IF(ISBLANK(M45),"",IF(LEN(M45)=20,"","ERROR")) | AU45: =IF(ISBLANK(N45),"",IF(AND(LEFT(N45,3)="CHE",ISNUMBER(MID(N45,4,9)+0),LEN(N45)=12),"","ERROR")) | AV45: =IF(COUNTIF(O$19:O$169,O45)>1,"Duplicate","") | AW45: =IF(ISBLANK(O45),"",IF(ABS(AC45-SUM(U45,V45,W45,X45,Y45,Z45,AA45,AB45))<=0.5,"","ERROR")) | AX45: =IF(ISBLANK(O45),"",IF(AC45+SUM(AD45,AE45,AF45,AG45)>=AH45-0.5,"","ERROR")) | AY45: =IF(ISBLANK(O45),"",IF(AH45>=AI45-0.5,"","ERROR")) | AZ45: =IF(ISBLANK(O45),"",IF(AI45>=AN45-0.5,"","ERROR")) | BA45: =IF(ISBLANK(O45),"",IF(T45>=0,"","ERROR")) | BB45: =IF(ISBLANK(O45),"",IF(COUNTIF(AD45:AG45,">0")>0,"ERROR","")) | BC45: =IF(ISBLANK(O45),"",IF(ISBLANK(AO45),"",IF(AO45>='Delivery Note'!$H$5,IF(AO45<='Delivery Note'!$H$5+92,"","ERROR"),"ERROR"))) | BD45: =IF(COUNTBLANK(K45:AP45)=32,"",IF(AND(COUNTIF(P$19:P$169,"G0T")>0,COUNTIF(P$19:P$169,"G1T")>0),IF(AND(OR(P45="G0T",P45="G1T"),OR(ISBLANK(AH45),AH45<0)),"WARNING",""),"WARNING")) | BE45: =IF(ISBLANK(P45),"",IF(AND(OR(P45="OTH", P45="PDT"), ISBLANK(AP45)), "WARNING", ""))
E46: 46 | P46: G1T | AC46: 0 | AH46: 0 | AI46: 0 | AJ46: =IF(P46="","",IFERROR(ROUND(IF(OR(P46="G0B",P46="G0T"),Tabelle5[[#This Row],[AI]]/SUM(LER_01!$L$26:$L$27),Tabelle5[[#This Row],[AI]]/(SUM(LER_01!$K$26:$K$27)+IF(LER_01!$D$10>=4,SUM(LER_01!$M$26:$M$27)))),3),"")) -> 0 | AK46: =IF(P46="","",IF(OR(P46="SOV",P46="SOB",P46="G0T",P46="G0B"),"",IF(AND(OR(P46="BSS",P46="BFS"),LER_01!$D$10<=2),15%,IF(AND(OR(P46="BSN",P46="BFN"),LER_01!$D$10>=4),100%,25%)))) -> 0.25 | AM46: 0 | AS46: =IF(COUNTBLANK(K46:AP46)=32,"",IF(OR(COUNTA(K46,L46,O46,P46,Q46,R46,S46,AC46,AH46,AI46,AM46)=11,AND(OR(P46="G1T",P46="G0T"),COUNTA(AH46)=1)),"","ERROR")) | AT46: =IF(ISBLANK(M46),"",IF(LEN(M46)=20,"","ERROR")) | AU46: =IF(ISBLANK(N46),"",IF(AND(LEFT(N46,3)="CHE",ISNUMBER(MID(N46,4,9)+0),LEN(N46)=12),"","ERROR")) | AV46: =IF(COUNTIF(O$19:O$169,O46)>1,"Duplicate","") | AW46: =IF(ISBLANK(O46),"",IF(ABS(AC46-SUM(U46,V46,W46,X46,Y46,Z46,AA46,AB46))<=0.5,"","ERROR")) | AX46: =IF(ISBLANK(O46),"",IF(AC46+SUM(AD46,AE46,AF46,AG46)>=AH46-0.5,"","ERROR")) | AY46: =IF(ISBLANK(O46),"",IF(AH46>=AI46-0.5,"","ERROR")) | AZ46: =IF(ISBLANK(O46),"",IF(AI46>=AN46-0.5,"","ERROR")) | BA46: =IF(ISBLANK(O46),"",IF(T46>=0,"","ERROR")) | BB46: =IF(ISBLANK(O46),"",IF(COUNTIF(AD46:AG46,">0")>0,"ERROR","")) | BC46: =IF(ISBLANK(O46),"",IF(ISBLANK(AO46),"",IF(AO46>='Delivery Note'!$H$5,IF(AO46<='Delivery Note'!$H$5+92,"","ERROR"),"ERROR"))) | BD46: =IF(COUNTBLANK(K46:AP46)=32,"",IF(AND(COUNTIF(P$19:P$169,"G0T")>0,COUNTIF(P$19:P$169,"G1T")>0),IF(AND(OR(P46="G0T",P46="G1T"),OR(ISBLANK(AH46),AH46<0)),"WARNING",""),"WARNING")) | BE46: =IF(ISBLANK(P46),"",IF(AND(OR(P46="OTH", P46="PDT"), ISBLANK(AP46)), "WARNING", ""))
E47: 47 | AJ47: =IF(P47="","",IFERROR(ROUND(IF(OR(P47="G0B",P47="G0T"),Tabelle5[[#This Row],[AI]]/SUM(LER_01!$L$26:$L$27),Tabelle5[[#This Row],[AI]]/(SUM(LER_01!$K$26:$K$27)+IF(LER_01!$D$10>=4,SUM(LER_01!$M$26:$M$27)))),3),"")) | AK47: =IF(P47="","",IF(OR(P47="SOV",P47="SOB",P47="G0T",P47="G0B"),"",IF(AND(OR(P47="BSS",P47="BFS"),LER_01!$D$10<=2),15%,IF(AND(OR(P47="BSN",P47="BFN"),LER_01!$D$10>=4),100%,25%)))) | AS47: =IF(COUNTBLANK(K47:AP47)=32,"",IF(OR(COUNTA(K47,L47,O47,P47,Q47,R47,S47,AC47,AH47,AI47,AM47)=11,AND(OR(P47="G1T",P47="G0T"),COUNTA(AH47)=1)),"","ERROR")) | AT47: =IF(ISBLANK(M47),"",IF(LEN(M47)=20,"","ERROR")) | AU47: =IF(ISBLANK(N47),"",IF(AND(LEFT(N47,3)="CHE",ISNUMBER(MID(N47,4,9)+0),LEN(N47)=12),"","ERROR")) | AV47: =IF(COUNTIF(O$19:O$169,O47)>1,"Duplicate","") | AW47: =IF(ISBLANK(O47),"",IF(ABS(AC47-SUM(U47,V47,W47,X47,Y47,Z47,AA47,AB47))<=0.5,"","ERROR")) | AX47: =IF(ISBLANK(O47),"",IF(AC47+SUM(AD47,AE47,AF47,AG47)>=AH47-0.5,"","ERROR")) | AY47: =IF(ISBLANK(O47),"",IF(AH47>=AI47-0.5,"","ERROR")) | AZ47: =IF(ISBLANK(O47),"",IF(AI47>=AN47-0.5,"","ERROR")) | BA47: =IF(ISBLANK(O47),"",IF(T47>=0,"","ERROR")) | BB47: =IF(ISBLANK(O47),"",IF(COUNTIF(AD47:AG47,">0")>0,"ERROR","")) | BC47: =IF(ISBLANK(O47),"",IF(ISBLANK(AO47),"",IF(AO47>='Delivery Note'!$H$5,IF(AO47<='Delivery Note'!$H$5+92,"","ERROR"),"ERROR"))) | BD47: =IF(COUNTBLANK(K47:AP47)=32,"",IF(AND(COUNTIF(P$19:P$169,"G0T")>0,COUNTIF(P$19:P$169,"G1T")>0),IF(AND(OR(P47="G0T",P47="G1T"),OR(ISBLANK(AH47),AH47<0)),"WARNING",""),"WARNING")) | BE47: =IF(ISBLANK(P47),"",IF(AND(OR(P47="OTH", P47="PDT"), ISBLANK(AP47)), "WARNING", ""))
